Workbook
Name OLE_LINK7: 元康盛景30号!$N$14

Sheet 申购数据-每日更新-0515
B1: 元康盛景17号 | C1: 元康盛景9号 | D1: 元康盛景20号 | E1: 元康盛景1号 | F1: 元康衡景1号私募证券投资基金B | G1: 元康盛景31号私募证券投资基金A | H1: 元康盛景28号A | I1: 元康盛景22号 | J1: 元康瑞景2号基础设施策略B | K1: 元康盛景29号私募证券投资基金 | L1: 元康全景1号私募证券投资基金B | M1: 元康盛景26号 | N1: 元康星辰量化4号
A2: 2026/05/15 | D2: 申购:雪球:16,300,000元,美市:1,035,000元 | F2: 申购:美市:1,000,000元 | G2: 申购:美市:14,000,000元 | H2: 申购:美市:3,250,000元 | M2: 申购:美市:4,500,000元 | N2: 赎回:美市:1,400,000份
A3: 2026/05/18 | G3: 申购:美市:1,500,000元 | H3: 赎回:美市:1,410,000份
A4: 2026/05/19 | C4: 赎回:联储:3,831,969份 | G4: 申购:美市:5,000,000元 | J4: 申购:美市:1,000,000元 | K4: 申购:美市:200,000元; 赎回:美市:700,000份 | L4: 申购:美市:100,000元
A5: 2026/05/20 | E5: 申购:美市:8,600,000元; 赎回:美市:2,722,460份
A6: 2026/05/21 | I6: 赎回:美市:6,889,278份
A7: 2026/05/25 | H7: 赎回:美市:1,240,000份
A8: 2026/05/26 | C8: 赎回:联储:5,899,357份 | D8: 赎回:雪球:1,102,424份,美市:1,324,389份 | I8: 赎回:美市:150,000份
A9: 2026/05/27 | H9: 赎回:美市:23,115,175份
A10: 2026/06/01 | H10: 赎回:美市:2,070,000份
A11: 2026/06/02 | K11: 赎回:美市:900,000份
A12: 2026/06/03 | B12: 赎回:雪球:681,199份 | E12: 赎回:美市:1,072,246份
A13: 2026/06/08 | H13: 赎回:美市:5,950,000份
A14: 2026/06/09 | I14: 赎回:美市:803,235份 | K14: 赎回:美市:290,000份
A15: 2026/06/10 | B15: 赎回:雪球:181,620份 | E15: 赎回:美市:107,225份
A16: 2026/06/16 | K16: 赎回:美市:1,000,000份
A17: 2026/06/22 | H17: 赎回:美市:28,430,000份
A18: 2026/06/24 | E18: 赎回:美市:59,785,584份 | L18: 申购:美市:100,000元 | N18: 申购:美市:100,000元
A19: 2026/06/25 | D19: 赎回:美市:2,403,376份 | I19: 赎回:美市:1,617,338份
A20: 2026/06/29 | H20: 赎回:美市:3,490,000份
A22: （内容由AI生成，仅供参考）

Sheet 汇总
A1: 日期 | B1: 元康盛景20号 | C1: 元康盛景26号 | D1: 元康盛景28号 | E1: 外贸信托_元康盛景1号 | F1: 苏信优先级Z2501 | G1: 苏信次级Z2502 | H1: 元康1号 | I1: 元康9号 | J1: 元康12号 | K1: 元康17号 | L1: 朗瑞1_5 | M1: 朗瑞1_8 | N1: 元康盛景29号 | O1: 元康盛景30号 | P1: 鹏雅119 | Q1: 鹏雅120 | R1: 中建投_臻泉2号 | S1: 慧聚领航1号 | T1: 苏信混合Z2603
A2: 46023 | B2: {=INDEX(_xlfn._xlws.FILTER(INDIRECT(B1&"!$E1:$E10000"),INDIRECT(B1&"!$a1:$a10000")=汇总!$A2),COUNTIF(INDIRECT(B1&"!$a1:$a10000"),汇总!$A2))} -> 619 | C2: {=INDEX(_xlfn._xlws.FILTER(INDIRECT(C1&"!$E1:$E10000"),INDIRECT(C1&"!$a1:$a10000")=汇总!$A2),COUNTIF(INDIRECT(C1&"!$a1:$a10000"),汇总!$A2))} -> 4182 | D2: {=INDEX(_xlfn._xlws.FILTER(INDIRECT(D1&"!$E1:$E10000"),INDIRECT(D1&"!$a1:$a10000")=汇总!$A2),COUNTIF(INDIRECT(D1&"!$a1:$a10000"),汇总!$A2))} -> 97 | E2: {=INDEX(_xlfn._xlws.FILTER(INDIRECT(E1&"!$E1:$E10000"),INDIRECT(E1&"!$a1:$a10000")=汇总!$A2),COUNTIF(INDIRECT(E1&"!$a1:$a10000"),汇总!$A2))} -> #VALUE! | F2: {=INDEX(_xlfn._xlws.FILTER(INDIRECT(F1&"!$E1:$E10000"),INDIRECT(F1&"!$a1:$a10000")=汇总!$A2),COUNTIF(INDIRECT(F1&"!$a1:$a10000"),汇总!$A2))} -> 192 | G2: {=INDEX(_xlfn._xlws.FILTER(INDIRECT(G1&"!$E1:$E10000"),INDIRECT(G1&"!$a1:$a10000")=汇总!$A2),COUNTIF(INDIRECT(G1&"!$a1:$a10000"),汇总!$A2))} -> 202 | H2: {=INDEX(_xlfn._xlws.FILTER(INDIRECT(H1&"!$E1:$E10000"),INDIRECT(H1&"!$a1:$a10000")=汇总!$A2),COUNTIF(INDIRECT(H1&"!$a1:$a10000"),汇总!$A2))} -> 151 | I2: {=INDEX(_xlfn._xlws.FILTER(INDIRECT(I1&"!$E1:$E10000"),INDIRECT(I1&"!$a1:$a10000")=汇总!$A2),COUNTIF(INDIRECT(I1&"!$a1:$a10000"),汇总!$A2))} -> 11 | ... S2: {=INDEX(_xlfn._xlws.FILTER(INDIRECT(S1&"!$E1:$E10000"),INDIRECT(S1&"!$a1:$a10000")=汇总!$A2),COUNTIF(INDIRECT(S1&"!$a1:$a10000"),汇总!$A2))} -> #VALUE!
A3: =+A2+1 -> 46024 | B3: {=IFERROR(INDEX(_xlfn._xlws.FILTER(INDIRECT(B$1&"!$E1:$E10000"),INDIRECT(B$1&"!$a1:$a10000")=汇总!$A3),COUNTIF(INDIRECT(B$1&"!$a1:$a10000"),汇总!$A3)),B2)} -> 619 | C3: {=IFERROR(INDEX(_xlfn._xlws.FILTER(INDIRECT(C$1&"!$E1:$E10000"),INDIRECT(C$1&"!$a1:$a10000")=汇总!$A3),COUNTIF(INDIRECT(C$1&"!$a1:$a10000"),汇总!$A3)),C2)} -> 4182 | D3: {=IFERROR(INDEX(_xlfn._xlws.FILTER(INDIRECT(D$1&"!$E1:$E10000"),INDIRECT(D$1&"!$a1:$a10000")=汇总!$A3),COUNTIF(INDIRECT(D$1&"!$a1:$a10000"),汇总!$A3)),D2)} -> 97 | E3: {=IFERROR(INDEX(_xlfn._xlws.FILTER(INDIRECT(E$1&"!$E1:$E10000"),INDIRECT(E$1&"!$a1:$a10000")=汇总!$A3),COUNTIF(INDIRECT(E$1&"!$a1:$a10000"),汇总!$A3)),E2)} -> #VALUE! | F3: {=IFERROR(INDEX(_xlfn._xlws.FILTER(INDIRECT(F$1&"!$E1:$E10000"),INDIRECT(F$1&"!$a1:$a10000")=汇总!$A3),COUNTIF(INDIRECT(F$1&"!$a1:$a10000"),汇总!$A3)),F2)} -> 192 | G3: {=IFERROR(INDEX(_xlfn._xlws.FILTER(INDIRECT(G$1&"!$E1:$E10000"),INDIRECT(G$1&"!$a1:$a10000")=汇总!$A3),COUNTIF(INDIRECT(G$1&"!$a1:$a10000"),汇总!$A3)),G2)} -> 202 | H3: {=IFERROR(INDEX(_xlfn._xlws.FILTER(INDIRECT(H$1&"!$E1:$E10000"),INDIRECT(H$1&"!$a1:$a10000")=汇总!$A3),COUNTIF(INDIRECT(H$1&"!$a1:$a10000"),汇总!$A3)),H2)} -> 151 | I3: {=IFERROR(INDEX(_xlfn._xlws.FILTER(INDIRECT(I$1&"!$E1:$E10000"),INDIRECT(I$1&"!$a1:$a10000")=汇总!$A3),COUNTIF(INDIRECT(I$1&"!$a1:$a10000"),汇总!$A3)),I2)} -> 11 | ... S3: {=IFERROR(INDEX(_xlfn._xlws.FILTER(INDIRECT(S$1&"!$E1:$E10000"),INDIRECT(S$1&"!$a1:$a10000")=汇总!$A3),COUNTIF(INDIRECT(S$1&"!$a1:$a10000"),汇总!$A3)),S2)} -> #VALUE!
A4: =+A3+1 -> 46025 | B4: {=IFERROR(INDEX(_xlfn._xlws.FILTER(INDIRECT(B$1&"!$E1:$E10000"),INDIRECT(B$1&"!$a1:$a10000")=汇总!$A4),COUNTIF(INDIRECT(B$1&"!$a1:$a10000"),汇总!$A4)),B3)} -> 619 | C4: {=IFERROR(INDEX(_xlfn._xlws.FILTER(INDIRECT(C$1&"!$E1:$E10000"),INDIRECT(C$1&"!$a1:$a10000")=汇总!$A4),COUNTIF(INDIRECT(C$1&"!$a1:$a10000"),汇总!$A4)),C3)} -> 4182 | D4: {=IFERROR(INDEX(_xlfn._xlws.FILTER(INDIRECT(D$1&"!$E1:$E10000"),INDIRECT(D$1&"!$a1:$a10000")=汇总!$A4),COUNTIF(INDIRECT(D$1&"!$a1:$a10000"),汇总!$A4)),D3)} -> 97 | E4: {=IFERROR(INDEX(_xlfn._xlws.FILTER(INDIRECT(E$1&"!$E1:$E10000"),INDIRECT(E$1&"!$a1:$a10000")=汇总!$A4),COUNTIF(INDIRECT(E$1&"!$a1:$a10000"),汇总!$A4)),E3)} -> #VALUE! | F4: {=IFERROR(INDEX(_xlfn._xlws.FILTER(INDIRECT(F$1&"!$E1:$E10000"),INDIRECT(F$1&"!$a1:$a10000")=汇总!$A4),COUNTIF(INDIRECT(F$1&"!$a1:$a10000"),汇总!$A4)),F3)} -> 192 | G4: {=IFERROR(INDEX(_xlfn._xlws.FILTER(INDIRECT(G$1&"!$E1:$E10000"),INDIRECT(G$1&"!$a1:$a10000")=汇总!$A4),COUNTIF(INDIRECT(G$1&"!$a1:$a10000"),汇总!$A4)),G3)} -> 202 | H4: {=IFERROR(INDEX(_xlfn._xlws.FILTER(INDIRECT(H$1&"!$E1:$E10000"),INDIRECT(H$1&"!$a1:$a10000")=汇总!$A4),COUNTIF(INDIRECT(H$1&"!$a1:$a10000"),汇总!$A4)),H3)} -> 151 | I4: {=IFERROR(INDEX(_xlfn._xlws.FILTER(INDIRECT(I$1&"!$E1:$E10000"),INDIRECT(I$1&"!$a1:$a10000")=汇总!$A4),COUNTIF(INDIRECT(I$1&"!$a1:$a10000"),汇总!$A4)),I3)} -> 11 | ... S4: {=IFERROR(INDEX(_xlfn._xlws.FILTER(INDIRECT(S$1&"!$E1:$E10000"),INDIRECT(S$1&"!$a1:$a10000")=汇总!$A4),COUNTIF(INDIRECT(S$1&"!$a1:$a10000"),汇总!$A4)),S3)} -> #VALUE!
A5: =+A4+1 -> 46026 | B5: {=IFERROR(INDEX(_xlfn._xlws.FILTER(INDIRECT(B$1&"!$E1:$E10000"),INDIRECT(B$1&"!$a1:$a10000")=汇总!$A5),COUNTIF(INDIRECT(B$1&"!$a1:$a10000"),汇总!$A5)),B4)} -> 619 | C5: {=IFERROR(INDEX(_xlfn._xlws.FILTER(INDIRECT(C$1&"!$E1:$E10000"),INDIRECT(C$1&"!$a1:$a10000")=汇总!$A5),COUNTIF(INDIRECT(C$1&"!$a1:$a10000"),汇总!$A5)),C4)} -> 4182 | D5: {=IFERROR(INDEX(_xlfn._xlws.FILTER(INDIRECT(D$1&"!$E1:$E10000"),INDIRECT(D$1&"!$a1:$a10000")=汇总!$A5),COUNTIF(INDIRECT(D$1&"!$a1:$a10000"),汇总!$A5)),D4)} -> 97 | E5: {=IFERROR(INDEX(_xlfn._xlws.FILTER(INDIRECT(E$1&"!$E1:$E10000"),INDIRECT(E$1&"!$a1:$a10000")=汇总!$A5),COUNTIF(INDIRECT(E$1&"!$a1:$a10000"),汇总!$A5)),E4)} -> #VALUE! | F5: {=IFERROR(INDEX(_xlfn._xlws.FILTER(INDIRECT(F$1&"!$E1:$E10000"),INDIRECT(F$1&"!$a1:$a10000")=汇总!$A5),COUNTIF(INDIRECT(F$1&"!$a1:$a10000"),汇总!$A5)),F4)} -> 192 | G5: {=IFERROR(INDEX(_xlfn._xlws.FILTER(INDIRECT(G$1&"!$E1:$E10000"),INDIRECT(G$1&"!$a1:$a10000")=汇总!$A5),COUNTIF(INDIRECT(G$1&"!$a1:$a10000"),汇总!$A5)),G4)} -> 202 | H5: {=IFERROR(INDEX(_xlfn._xlws.FILTER(INDIRECT(H$1&"!$E1:$E10000"),INDIRECT(H$1&"!$a1:$a10000")=汇总!$A5),COUNTIF(INDIRECT(H$1&"!$a1:$a10000"),汇总!$A5)),H4)} -> 151 | I5: {=IFERROR(INDEX(_xlfn._xlws.FILTER(INDIRECT(I$1&"!$E1:$E10000"),INDIRECT(I$1&"!$a1:$a10000")=汇总!$A5),COUNTIF(INDIRECT(I$1&"!$a1:$a10000"),汇总!$A5)),I4)} -> 11 | ... S5: {=IFERROR(INDEX(_xlfn._xlws.FILTER(INDIRECT(S$1&"!$E1:$E10000"),INDIRECT(S$1&"!$a1:$a10000")=汇总!$A5),COUNTIF(INDIRECT(S$1&"!$a1:$a10000"),汇总!$A5)),S4)} -> #VALUE!
A6: =+A5+1 -> 46027 | B6: {=IFERROR(INDEX(_xlfn._xlws.FILTER(INDIRECT(B$1&"!$E1:$E10000"),INDIRECT(B$1&"!$a1:$a10000")=汇总!$A6),COUNTIF(INDIRECT(B$1&"!$a1:$a10000"),汇总!$A6)),B5)} -> 619 | C6: {=IFERROR(INDEX(_xlfn._xlws.FILTER(INDIRECT(C$1&"!$E1:$E10000"),INDIRECT(C$1&"!$a1:$a10000")=汇总!$A6),COUNTIF(INDIRECT(C$1&"!$a1:$a10000"),汇总!$A6)),C5)} -> 2377 | D6: {=IFERROR(INDEX(_xlfn._xlws.FILTER(INDIRECT(D$1&"!$E1:$E10000"),INDIRECT(D$1&"!$a1:$a10000")=汇总!$A6),COUNTIF(INDIRECT(D$1&"!$a1:$a10000"),汇总!$A6)),D5)} -> 97 | E6: {=IFERROR(INDEX(_xlfn._xlws.FILTER(INDIRECT(E$1&"!$E1:$E10000"),INDIRECT(E$1&"!$a1:$a10000")=汇总!$A6),COUNTIF(INDIRECT(E$1&"!$a1:$a10000"),汇总!$A6)),E5)} -> #VALUE! | F6: {=IFERROR(INDEX(_xlfn._xlws.FILTER(INDIRECT(F$1&"!$E1:$E10000"),INDIRECT(F$1&"!$a1:$a10000")=汇总!$A6),COUNTIF(INDIRECT(F$1&"!$a1:$a10000"),汇总!$A6)),F5)} -> 192 | G6: {=IFERROR(INDEX(_xlfn._xlws.FILTER(INDIRECT(G$1&"!$E1:$E10000"),INDIRECT(G$1&"!$a1:$a10000")=汇总!$A6),COUNTIF(INDIRECT(G$1&"!$a1:$a10000"),汇总!$A6)),G5)} -> 202 | H6: {=IFERROR(INDEX(_xlfn._xlws.FILTER(INDIRECT(H$1&"!$E1:$E10000"),INDIRECT(H$1&"!$a1:$a10000")=汇总!$A6),COUNTIF(INDIRECT(H$1&"!$a1:$a10000"),汇总!$A6)),H5)} -> 151 | I6: {=IFERROR(INDEX(_xlfn._xlws.FILTER(INDIRECT(I$1&"!$E1:$E10000"),INDIRECT(I$1&"!$a1:$a10000")=汇总!$A6),COUNTIF(INDIRECT(I$1&"!$a1:$a10000"),汇总!$A6)),I5)} -> 11 | ... S6: {=IFERROR(INDEX(_xlfn._xlws.FILTER(INDIRECT(S$1&"!$E1:$E10000"),INDIRECT(S$1&"!$a1:$a10000")=汇总!$A6),COUNTIF(INDIRECT(S$1&"!$a1:$a10000"),汇总!$A6)),S5)} -> #VALUE!
A7: =+A6+1 -> 46028 | B7: {=IFERROR(INDEX(_xlfn._xlws.FILTER(INDIRECT(B$1&"!$E1:$E10000"),INDIRECT(B$1&"!$a1:$a10000")=汇总!$A7),COUNTIF(INDIRECT(B$1&"!$a1:$a10000"),汇总!$A7)),B6)} -> 619 | C7: {=IFERROR(INDEX(_xlfn._xlws.FILTER(INDIRECT(C$1&"!$E1:$E10000"),INDIRECT(C$1&"!$a1:$a10000")=汇总!$A7),COUNTIF(INDIRECT(C$1&"!$a1:$a10000"),汇总!$A7)),C6)} -> 2377 | D7: {=IFERROR(INDEX(_xlfn._xlws.FILTER(INDIRECT(D$1&"!$E1:$E10000"),INDIRECT(D$1&"!$a1:$a10000")=汇总!$A7),COUNTIF(INDIRECT(D$1&"!$a1:$a10000"),汇总!$A7)),D6)} -> 97 | E7: {=IFERROR(INDEX(_xlfn._xlws.FILTER(INDIRECT(E$1&"!$E1:$E10000"),INDIRECT(E$1&"!$a1:$a10000")=汇总!$A7),COUNTIF(INDIRECT(E$1&"!$a1:$a10000"),汇总!$A7)),E6)} -> 295.8 | F7: {=IFERROR(INDEX(_xlfn._xlws.FILTER(INDIRECT(F$1&"!$E1:$E10000"),INDIRECT(F$1&"!$a1:$a10000")=汇总!$A7),COUNTIF(INDIRECT(F$1&"!$a1:$a10000"),汇总!$A7)),F6)} -> 192 | G7: {=IFERROR(INDEX(_xlfn._xlws.FILTER(INDIRECT(G$1&"!$E1:$E10000"),INDIRECT(G$1&"!$a1:$a10000")=汇总!$A7),COUNTIF(INDIRECT(G$1&"!$a1:$a10000"),汇总!$A7)),G6)} -> 202 | H7: {=IFERROR(INDEX(_xlfn._xlws.FILTER(INDIRECT(H$1&"!$E1:$E10000"),INDIRECT(H$1&"!$a1:$a10000")=汇总!$A7),COUNTIF(INDIRECT(H$1&"!$a1:$a10000"),汇总!$A7)),H6)} -> 601 | I7: {=IFERROR(INDEX(_xlfn._xlws.FILTER(INDIRECT(I$1&"!$E1:$E10000"),INDIRECT(I$1&"!$a1:$a10000")=汇总!$A7),COUNTIF(INDIRECT(I$1&"!$a1:$a10000"),汇总!$A7)),I6)} -> 11 | ... S7: {=IFERROR(INDEX(_xlfn._xlws.FILTER(INDIRECT(S$1&"!$E1:$E10000"),INDIRECT(S$1&"!$a1:$a10000")=汇总!$A7),COUNTIF(INDIRECT(S$1&"!$a1:$a10000"),汇总!$A7)),S6)} -> #VALUE!
A8: =+A7+1 -> 46029 | B8: {=IFERROR(INDEX(_xlfn._xlws.FILTER(INDIRECT(B$1&"!$E1:$E10000"),INDIRECT(B$1&"!$a1:$a10000")=汇总!$A8),COUNTIF(INDIRECT(B$1&"!$a1:$a10000"),汇总!$A8)),B7)} -> 164 | C8: {=IFERROR(INDEX(_xlfn._xlws.FILTER(INDIRECT(C$1&"!$E1:$E10000"),INDIRECT(C$1&"!$a1:$a10000")=汇总!$A8),COUNTIF(INDIRECT(C$1&"!$a1:$a10000"),汇总!$A8)),C7)} -> 253 | D8: {=IFERROR(INDEX(_xlfn._xlws.FILTER(INDIRECT(D$1&"!$E1:$E10000"),INDIRECT(D$1&"!$a1:$a10000")=汇总!$A8),COUNTIF(INDIRECT(D$1&"!$a1:$a10000"),汇总!$A8)),D7)} -> 97 | E8: {=IFERROR(INDEX(_xlfn._xlws.FILTER(INDIRECT(E$1&"!$E1:$E10000"),INDIRECT(E$1&"!$a1:$a10000")=汇总!$A8),COUNTIF(INDIRECT(E$1&"!$a1:$a10000"),汇总!$A8)),E7)} -> 4613.7975 | F8: {=IFERROR(INDEX(_xlfn._xlws.FILTER(INDIRECT(F$1&"!$E1:$E10000"),INDIRECT(F$1&"!$a1:$a10000")=汇总!$A8),COUNTIF(INDIRECT(F$1&"!$a1:$a10000"),汇总!$A8)),F7)} -> 192 | G8: {=IFERROR(INDEX(_xlfn._xlws.FILTER(INDIRECT(G$1&"!$E1:$E10000"),INDIRECT(G$1&"!$a1:$a10000")=汇总!$A8),COUNTIF(INDIRECT(G$1&"!$a1:$a10000"),汇总!$A8)),G7)} -> 202 | H8: {=IFERROR(INDEX(_xlfn._xlws.FILTER(INDIRECT(H$1&"!$E1:$E10000"),INDIRECT(H$1&"!$a1:$a10000")=汇总!$A8),COUNTIF(INDIRECT(H$1&"!$a1:$a10000"),汇总!$A8)),H7)} -> 601 | I8: {=IFERROR(INDEX(_xlfn._xlws.FILTER(INDIRECT(I$1&"!$E1:$E10000"),INDIRECT(I$1&"!$a1:$a10000")=汇总!$A8),COUNTIF(INDIRECT(I$1&"!$a1:$a10000"),汇总!$A8)),I7)} -> 11 | ... S8: {=IFERROR(INDEX(_xlfn._xlws.FILTER(INDIRECT(S$1&"!$E1:$E10000"),INDIRECT(S$1&"!$a1:$a10000")=汇总!$A8),COUNTIF(INDIRECT(S$1&"!$a1:$a10000"),汇总!$A8)),S7)} -> #VALUE!
A9: =+A8+1 -> 46030 | B9: {=IFERROR(INDEX(_xlfn._xlws.FILTER(INDIRECT(B$1&"!$E1:$E10000"),INDIRECT(B$1&"!$a1:$a10000")=汇总!$A9),COUNTIF(INDIRECT(B$1&"!$a1:$a10000"),汇总!$A9)),B8)} -> 164 | C9: {=IFERROR(INDEX(_xlfn._xlws.FILTER(INDIRECT(C$1&"!$E1:$E10000"),INDIRECT(C$1&"!$a1:$a10000")=汇总!$A9),COUNTIF(INDIRECT(C$1&"!$a1:$a10000"),汇总!$A9)),C8)} -> 2486 | D9: {=IFERROR(INDEX(_xlfn._xlws.FILTER(INDIRECT(D$1&"!$E1:$E10000"),INDIRECT(D$1&"!$a1:$a10000")=汇总!$A9),COUNTIF(INDIRECT(D$1&"!$a1:$a10000"),汇总!$A9)),D8)} -> 97 | E9: {=IFERROR(INDEX(_xlfn._xlws.FILTER(INDIRECT(E$1&"!$E1:$E10000"),INDIRECT(E$1&"!$a1:$a10000")=汇总!$A9),COUNTIF(INDIRECT(E$1&"!$a1:$a10000"),汇总!$A9)),E8)} -> 1100.2633 | F9: {=IFERROR(INDEX(_xlfn._xlws.FILTER(INDIRECT(F$1&"!$E1:$E10000"),INDIRECT(F$1&"!$a1:$a10000")=汇总!$A9),COUNTIF(INDIRECT(F$1&"!$a1:$a10000"),汇总!$A9)),F8)} -> 199.56 | G9: {=IFERROR(INDEX(_xlfn._xlws.FILTER(INDIRECT(G$1&"!$E1:$E10000"),INDIRECT(G$1&"!$a1:$a10000")=汇总!$A9),COUNTIF(INDIRECT(G$1&"!$a1:$a10000"),汇总!$A9)),G8)} -> 202 | H9: {=IFERROR(INDEX(_xlfn._xlws.FILTER(INDIRECT(H$1&"!$E1:$E10000"),INDIRECT(H$1&"!$a1:$a10000")=汇总!$A9),COUNTIF(INDIRECT(H$1&"!$a1:$a10000"),汇总!$A9)),H8)} -> 601 | I9: {=IFERROR(INDEX(_xlfn._xlws.FILTER(INDIRECT(I$1&"!$E1:$E10000"),INDIRECT(I$1&"!$a1:$a10000")=汇总!$A9),COUNTIF(INDIRECT(I$1&"!$a1:$a10000"),汇总!$A9)),I8)} -> 11 | ... S9: {=IFERROR(INDEX(_xlfn._xlws.FILTER(INDIRECT(S$1&"!$E1:$E10000"),INDIRECT(S$1&"!$a1:$a10000")=汇总!$A9),COUNTIF(INDIRECT(S$1&"!$a1:$a10000"),汇总!$A9)),S8)} -> #VALUE!
A10: =+A9+1 -> 46031 | B10: {=IFERROR(INDEX(_xlfn._xlws.FILTER(INDIRECT(B$1&"!$E1:$E10000"),INDIRECT(B$1&"!$a1:$a10000")=汇总!$A10),COUNTIF(INDIRECT(B$1&"!$a1:$a10000"),汇总!$A10)),B9)} -> 466 | C10: {=IFERROR(INDEX(_xlfn._xlws.FILTER(INDIRECT(C$1&"!$E1:$E10000"),INDIRECT(C$1&"!$a1:$a10000")=汇总!$A10),COUNTIF(INDIRECT(C$1&"!$a1:$a10000"),汇总!$A10)),C9)} -> 2486 | D10: {=IFERROR(INDEX(_xlfn._xlws.FILTER(INDIRECT(D$1&"!$E1:$E10000"),INDIRECT(D$1&"!$a1:$a10000")=汇总!$A10),COUNTIF(INDIRECT(D$1&"!$a1:$a10000"),汇总!$A10)),D9)} -> 597 | E10: {=IFERROR(INDEX(_xlfn._xlws.FILTER(INDIRECT(E$1&"!$E1:$E10000"),INDIRECT(E$1&"!$a1:$a10000")=汇总!$A10),COUNTIF(INDIRECT(E$1&"!$a1:$a10000"),汇总!$A10)),E9)} -> 1100.2633 | F10: {=IFERROR(INDEX(_xlfn._xlws.FILTER(INDIRECT(F$1&"!$E1:$E10000"),INDIRECT(F$1&"!$a1:$a10000")=汇总!$A10),COUNTIF(INDIRECT(F$1&"!$a1:$a10000"),汇总!$A10)),F9)} -> 199.56 | G10: {=IFERROR(INDEX(_xlfn._xlws.FILTER(INDIRECT(G$1&"!$E1:$E10000"),INDIRECT(G$1&"!$a1:$a10000")=汇总!$A10),COUNTIF(INDIRECT(G$1&"!$a1:$a10000"),汇总!$A10)),G9)} -> 93.352 | H10: {=IFERROR(INDEX(_xlfn._xlws.FILTER(INDIRECT(H$1&"!$E1:$E10000"),INDIRECT(H$1&"!$a1:$a10000")=汇总!$A10),COUNTIF(INDIRECT(H$1&"!$a1:$a10000"),汇总!$A10)),H9)} -> 48.7 | I10: {=IFERROR(INDEX(_xlfn._xlws.FILTER(INDIRECT(I$1&"!$E1:$E10000"),INDIRECT(I$1&"!$a1:$a10000")=汇总!$A10),COUNTIF(INDIRECT(I$1&"!$a1:$a10000"),汇总!$A10)),I9)} -> 11 | ... S10: {=IFERROR(INDEX(_xlfn._xlws.FILTER(INDIRECT(S$1&"!$E1:$E10000"),INDIRECT(S$1&"!$a1:$a10000")=汇总!$A10),COUNTIF(INDIRECT(S$1&"!$a1:$a10000"),汇总!$A10)),S9)} -> #VALUE!
A11: =+A10+1 -> 46032 | B11: {=IFERROR(INDEX(_xlfn._xlws.FILTER(INDIRECT(B$1&"!$E1:$E10000"),INDIRECT(B$1&"!$a1:$a10000")=汇总!$A11),COUNTIF(INDIRECT(B$1&"!$a1:$a10000"),汇总!$A11)),B10)} -> 466 | C11: {=IFERROR(INDEX(_xlfn._xlws.FILTER(INDIRECT(C$1&"!$E1:$E10000"),INDIRECT(C$1&"!$a1:$a10000")=汇总!$A11),COUNTIF(INDIRECT(C$1&"!$a1:$a10000"),汇总!$A11)),C10)} -> 2486 | D11: {=IFERROR(INDEX(_xlfn._xlws.FILTER(INDIRECT(D$1&"!$E1:$E10000"),INDIRECT(D$1&"!$a1:$a10000")=汇总!$A11),COUNTIF(INDIRECT(D$1&"!$a1:$a10000"),汇总!$A11)),D10)} -> 597 | E11: {=IFERROR(INDEX(_xlfn._xlws.FILTER(INDIRECT(E$1&"!$E1:$E10000"),INDIRECT(E$1&"!$a1:$a10000")=汇总!$A11),COUNTIF(INDIRECT(E$1&"!$a1:$a10000"),汇总!$A11)),E10)} -> 1100.2633 | F11: {=IFERROR(INDEX(_xlfn._xlws.FILTER(INDIRECT(F$1&"!$E1:$E10000"),INDIRECT(F$1&"!$a1:$a10000")=汇总!$A11),COUNTIF(INDIRECT(F$1&"!$a1:$a10000"),汇总!$A11)),F10)} -> 199.56 | G11: {=IFERROR(INDEX(_xlfn._xlws.FILTER(INDIRECT(G$1&"!$E1:$E10000"),INDIRECT(G$1&"!$a1:$a10000")=汇总!$A11),COUNTIF(INDIRECT(G$1&"!$a1:$a10000"),汇总!$A11)),G10)} -> 93.352 | H11: {=IFERROR(INDEX(_xlfn._xlws.FILTER(INDIRECT(H$1&"!$E1:$E10000"),INDIRECT(H$1&"!$a1:$a10000")=汇总!$A11),COUNTIF(INDIRECT(H$1&"!$a1:$a10000"),汇总!$A11)),H10)} -> 48.7 | I11: {=IFERROR(INDEX(_xlfn._xlws.FILTER(INDIRECT(I$1&"!$E1:$E10000"),INDIRECT(I$1&"!$a1:$a10000")=汇总!$A11),COUNTIF(INDIRECT(I$1&"!$a1:$a10000"),汇总!$A11)),I10)} -> 11 | ... S11: {=IFERROR(INDEX(_xlfn._xlws.FILTER(INDIRECT(S$1&"!$E1:$E10000"),INDIRECT(S$1&"!$a1:$a10000")=汇总!$A11),COUNTIF(INDIRECT(S$1&"!$a1:$a10000"),汇总!$A11)),S10)} -> #VALUE!
A12: =+A11+1 -> 46033 | B12: {=IFERROR(INDEX(_xlfn._xlws.FILTER(INDIRECT(B$1&"!$E1:$E10000"),INDIRECT(B$1&"!$a1:$a10000")=汇总!$A12),COUNTIF(INDIRECT(B$1&"!$a1:$a10000"),汇总!$A12)),B11)} -> 466 | C12: {=IFERROR(INDEX(_xlfn._xlws.FILTER(INDIRECT(C$1&"!$E1:$E10000"),INDIRECT(C$1&"!$a1:$a10000")=汇总!$A12),COUNTIF(INDIRECT(C$1&"!$a1:$a10000"),汇总!$A12)),C11)} -> 2486 | D12: {=IFERROR(INDEX(_xlfn._xlws.FILTER(INDIRECT(D$1&"!$E1:$E10000"),INDIRECT(D$1&"!$a1:$a10000")=汇总!$A12),COUNTIF(INDIRECT(D$1&"!$a1:$a10000"),汇总!$A12)),D11)} -> 597 | E12: {=IFERROR(INDEX(_xlfn._xlws.FILTER(INDIRECT(E$1&"!$E1:$E10000"),INDIRECT(E$1&"!$a1:$a10000")=汇总!$A12),COUNTIF(INDIRECT(E$1&"!$a1:$a10000"),汇总!$A12)),E11)} -> 1100.2633 | F12: {=IFERROR(INDEX(_xlfn._xlws.FILTER(INDIRECT(F$1&"!$E1:$E10000"),INDIRECT(F$1&"!$a1:$a10000")=汇总!$A12),COUNTIF(INDIRECT(F$1&"!$a1:$a10000"),汇总!$A12)),F11)} -> 199.56 | G12: {=IFERROR(INDEX(_xlfn._xlws.FILTER(INDIRECT(G$1&"!$E1:$E10000"),INDIRECT(G$1&"!$a1:$a10000")=汇总!$A12),COUNTIF(INDIRECT(G$1&"!$a1:$a10000"),汇总!$A12)),G11)} -> 93.352 | H12: {=IFERROR(INDEX(_xlfn._xlws.FILTER(INDIRECT(H$1&"!$E1:$E10000"),INDIRECT(H$1&"!$a1:$a10000")=汇总!$A12),COUNTIF(INDIRECT(H$1&"!$a1:$a10000"),汇总!$A12)),H11)} -> 48.7 | I12: {=IFERROR(INDEX(_xlfn._xlws.FILTER(INDIRECT(I$1&"!$E1:$E10000"),INDIRECT(I$1&"!$a1:$a10000")=汇总!$A12),COUNTIF(INDIRECT(I$1&"!$a1:$a10000"),汇总!$A12)),I11)} -> 11 | ... S12: {=IFERROR(INDEX(_xlfn._xlws.FILTER(INDIRECT(S$1&"!$E1:$E10000"),INDIRECT(S$1&"!$a1:$a10000")=汇总!$A12),COUNTIF(INDIRECT(S$1&"!$a1:$a10000"),汇总!$A12)),S11)} -> #VALUE!
A13: =+A12+1 -> 46034 | B13: {=IFERROR(INDEX(_xlfn._xlws.FILTER(INDIRECT(B$1&"!$E1:$E10000"),INDIRECT(B$1&"!$a1:$a10000")=汇总!$A13),COUNTIF(INDIRECT(B$1&"!$a1:$a10000"),汇总!$A13)),B12)} -> 764.5 | C13: {=IFERROR(INDEX(_xlfn._xlws.FILTER(INDIRECT(C$1&"!$E1:$E10000"),INDIRECT(C$1&"!$a1:$a10000")=汇总!$A13),COUNTIF(INDIRECT(C$1&"!$a1:$a10000"),汇总!$A13)),C12)} -> 258 | D13: {=IFERROR(INDEX(_xlfn._xlws.FILTER(INDIRECT(D$1&"!$E1:$E10000"),INDIRECT(D$1&"!$a1:$a10000")=汇总!$A13),COUNTIF(INDIRECT(D$1&"!$a1:$a10000"),汇总!$A13)),D12)} -> 173.75875 | E13: {=IFERROR(INDEX(_xlfn._xlws.FILTER(INDIRECT(E$1&"!$E1:$E10000"),INDIRECT(E$1&"!$a1:$a10000")=汇总!$A13),COUNTIF(INDIRECT(E$1&"!$a1:$a10000"),汇总!$A13)),E12)} -> 1100.2633 | F13: {=IFERROR(INDEX(_xlfn._xlws.FILTER(INDIRECT(F$1&"!$E1:$E10000"),INDIRECT(F$1&"!$a1:$a10000")=汇总!$A13),COUNTIF(INDIRECT(F$1&"!$a1:$a10000"),汇总!$A13)),F12)} -> 204.71 | G13: {=IFERROR(INDEX(_xlfn._xlws.FILTER(INDIRECT(G$1&"!$E1:$E10000"),INDIRECT(G$1&"!$a1:$a10000")=汇总!$A13),COUNTIF(INDIRECT(G$1&"!$a1:$a10000"),汇总!$A13)),G12)} -> 93.352 | H13: {=IFERROR(INDEX(_xlfn._xlws.FILTER(INDIRECT(H$1&"!$E1:$E10000"),INDIRECT(H$1&"!$a1:$a10000")=汇总!$A13),COUNTIF(INDIRECT(H$1&"!$a1:$a10000"),汇总!$A13)),H12)} -> 48.7 | I13: {=IFERROR(INDEX(_xlfn._xlws.FILTER(INDIRECT(I$1&"!$E1:$E10000"),INDIRECT(I$1&"!$a1:$a10000")=汇总!$A13),COUNTIF(INDIRECT(I$1&"!$a1:$a10000"),汇总!$A13)),I12)} -> 11 | ... S13: {=IFERROR(INDEX(_xlfn._xlws.FILTER(INDIRECT(S$1&"!$E1:$E10000"),INDIRECT(S$1&"!$a1:$a10000")=汇总!$A13),COUNTIF(INDIRECT(S$1&"!$a1:$a10000"),汇总!$A13)),S12)} -> #VALUE!
A14: =+A13+1 -> 46035 | B14: {=IFERROR(INDEX(_xlfn._xlws.FILTER(INDIRECT(B$1&"!$E1:$E10000"),INDIRECT(B$1&"!$a1:$a10000")=汇总!$A14),COUNTIF(INDIRECT(B$1&"!$a1:$a10000"),汇总!$A14)),B13)} -> 232.4 | C14: {=IFERROR(INDEX(_xlfn._xlws.FILTER(INDIRECT(C$1&"!$E1:$E10000"),INDIRECT(C$1&"!$a1:$a10000")=汇总!$A14),COUNTIF(INDIRECT(C$1&"!$a1:$a10000"),汇总!$A14)),C13)} -> 708 | D14: {=IFERROR(INDEX(_xlfn._xlws.FILTER(INDIRECT(D$1&"!$E1:$E10000"),INDIRECT(D$1&"!$a1:$a10000")=汇总!$A14),COUNTIF(INDIRECT(D$1&"!$a1:$a10000"),汇总!$A14)),D13)} -> 369.021 | E14: {=IFERROR(INDEX(_xlfn._xlws.FILTER(INDIRECT(E$1&"!$E1:$E10000"),INDIRECT(E$1&"!$a1:$a10000")=汇总!$A14),COUNTIF(INDIRECT(E$1&"!$a1:$a10000"),汇总!$A14)),E13)} -> 1100.2633 | F14: {=IFERROR(INDEX(_xlfn._xlws.FILTER(INDIRECT(F$1&"!$E1:$E10000"),INDIRECT(F$1&"!$a1:$a10000")=汇总!$A14),COUNTIF(INDIRECT(F$1&"!$a1:$a10000"),汇总!$A14)),F13)} -> 204.71 | G14: {=IFERROR(INDEX(_xlfn._xlws.FILTER(INDIRECT(G$1&"!$E1:$E10000"),INDIRECT(G$1&"!$a1:$a10000")=汇总!$A14),COUNTIF(INDIRECT(G$1&"!$a1:$a10000"),汇总!$A14)),G13)} -> 93.352 | H14: {=IFERROR(INDEX(_xlfn._xlws.FILTER(INDIRECT(H$1&"!$E1:$E10000"),INDIRECT(H$1&"!$a1:$a10000")=汇总!$A14),COUNTIF(INDIRECT(H$1&"!$a1:$a10000"),汇总!$A14)),H13)} -> 48.7 | I14: {=IFERROR(INDEX(_xlfn._xlws.FILTER(INDIRECT(I$1&"!$E1:$E10000"),INDIRECT(I$1&"!$a1:$a10000")=汇总!$A14),COUNTIF(INDIRECT(I$1&"!$a1:$a10000"),汇总!$A14)),I13)} -> 11 | ... S14: {=IFERROR(INDEX(_xlfn._xlws.FILTER(INDIRECT(S$1&"!$E1:$E10000"),INDIRECT(S$1&"!$a1:$a10000")=汇总!$A14),COUNTIF(INDIRECT(S$1&"!$a1:$a10000"),汇总!$A14)),S13)} -> #VALUE!
... A97: =+A96+1 -> 46118 | B97: {=IFERROR(INDEX(_xlfn._xlws.FILTER(INDIRECT(B$1&"!$E1:$E10000"),INDIRECT(B$1&"!$a1:$a10000")=汇总!$A97),COUNTIF(INDIRECT(B$1&"!$a1:$a10000"),汇总!$A97)),B96)} -> 2136.9726 | C97: {=IFERROR(INDEX(_xlfn._xlws.FILTER(INDIRECT(C$1&"!$E1:$E10000"),INDIRECT(C$1&"!$a1:$a10000")=汇总!$A97),COUNTIF(INDIRECT(C$1&"!$a1:$a10000"),汇总!$A97)),C96)} -> 1799.0525 | D97: {=IFERROR(INDEX(_xlfn._xlws.FILTER(INDIRECT(D$1&"!$E1:$E10000"),INDIRECT(D$1&"!$a1:$a10000")=汇总!$A97),COUNTIF(INDIRECT(D$1&"!$a1:$a10000"),汇总!$A97)),D96)} -> 2104.7305 | E97: {=IFERROR(INDEX(_xlfn._xlws.FILTER(INDIRECT(E$1&"!$E1:$E10000"),INDIRECT(E$1&"!$a1:$a10000")=汇总!$A97),COUNTIF(INDIRECT(E$1&"!$a1:$a10000"),汇总!$A97)),E96)} -> 3235 | F97: {=IFERROR(INDEX(_xlfn._xlws.FILTER(INDIRECT(F$1&"!$E1:$E10000"),INDIRECT(F$1&"!$a1:$a10000")=汇总!$A97),COUNTIF(INDIRECT(F$1&"!$a1:$a10000"),汇总!$A97)),F96)} -> 7350 | G97: {=IFERROR(INDEX(_xlfn._xlws.FILTER(INDIRECT(G$1&"!$E1:$E10000"),INDIRECT(G$1&"!$a1:$a10000")=汇总!$A97),COUNTIF(INDIRECT(G$1&"!$a1:$a10000"),汇总!$A97)),G96)} -> 6771.4 | H97: {=IFERROR(INDEX(_xlfn._xlws.FILTER(INDIRECT(H$1&"!$E1:$E10000"),INDIRECT(H$1&"!$a1:$a10000")=汇总!$A97),COUNTIF(INDIRECT(H$1&"!$a1:$a10000"),汇总!$A97)),H96)} -> 431.92997 | I97: {=IFERROR(INDEX(_xlfn._xlws.FILTER(INDIRECT(I$1&"!$E1:$E10000"),INDIRECT(I$1&"!$a1:$a10000")=汇总!$A97),COUNTIF(INDIRECT(I$1&"!$a1:$a10000"),汇总!$A97)),I96)} -> 834.68823 | ... S97: {=IFERROR(INDEX(_xlfn._xlws.FILTER(INDIRECT(S$1&"!$E1:$E10000"),INDIRECT(S$1&"!$a1:$a10000")=汇总!$A97),COUNTIF(INDIRECT(S$1&"!$a1:$a10000"),汇总!$A97)),S96)} -> 107.36596
A98: =+A97+1 -> 46119 | B98: {=IFERROR(INDEX(_xlfn._xlws.FILTER(INDIRECT(B$1&"!$E1:$E10000"),INDIRECT(B$1&"!$a1:$a10000")=汇总!$A98),COUNTIF(INDIRECT(B$1&"!$a1:$a10000"),汇总!$A98)),B97)} -> 382.97263 | C98: {=IFERROR(INDEX(_xlfn._xlws.FILTER(INDIRECT(C$1&"!$E1:$E10000"),INDIRECT(C$1&"!$a1:$a10000")=汇总!$A98),COUNTIF(INDIRECT(C$1&"!$a1:$a10000"),汇总!$A98)),C97)} -> 1799.0525 | D98: {=IFERROR(INDEX(_xlfn._xlws.FILTER(INDIRECT(D$1&"!$E1:$E10000"),INDIRECT(D$1&"!$a1:$a10000")=汇总!$A98),COUNTIF(INDIRECT(D$1&"!$a1:$a10000"),汇总!$A98)),D97)} -> 2104.7305 | E98: {=IFERROR(INDEX(_xlfn._xlws.FILTER(INDIRECT(E$1&"!$E1:$E10000"),INDIRECT(E$1&"!$a1:$a10000")=汇总!$A98),COUNTIF(INDIRECT(E$1&"!$a1:$a10000"),汇总!$A98)),E97)} -> 3235 | F98: {=IFERROR(INDEX(_xlfn._xlws.FILTER(INDIRECT(F$1&"!$E1:$E10000"),INDIRECT(F$1&"!$a1:$a10000")=汇总!$A98),COUNTIF(INDIRECT(F$1&"!$a1:$a10000"),汇总!$A98)),F97)} -> 7350 | G98: {=IFERROR(INDEX(_xlfn._xlws.FILTER(INDIRECT(G$1&"!$E1:$E10000"),INDIRECT(G$1&"!$a1:$a10000")=汇总!$A98),COUNTIF(INDIRECT(G$1&"!$a1:$a10000"),汇总!$A98)),G97)} -> 6771.4 | H98: {=IFERROR(INDEX(_xlfn._xlws.FILTER(INDIRECT(H$1&"!$E1:$E10000"),INDIRECT(H$1&"!$a1:$a10000")=汇总!$A98),COUNTIF(INDIRECT(H$1&"!$a1:$a10000"),汇总!$A98)),H97)} -> 431.92997 | I98: {=IFERROR(INDEX(_xlfn._xlws.FILTER(INDIRECT(I$1&"!$E1:$E10000"),INDIRECT(I$1&"!$a1:$a10000")=汇总!$A98),COUNTIF(INDIRECT(I$1&"!$a1:$a10000"),汇总!$A98)),I97)} -> 171.20811 | ... T98: {=IFERROR(INDEX(_xlfn._xlws.FILTER(INDIRECT(T$1&"!$E1:$E10000"),INDIRECT(T$1&"!$a1:$a10000")=汇总!$A98),COUNTIF(INDIRECT(T$1&"!$a1:$a10000"),汇总!$A98)),T97)} -> 0
A99: =+A98+1 -> 46120 | B99: {=IFERROR(INDEX(_xlfn._xlws.FILTER(INDIRECT(B$1&"!$E1:$E10000"),INDIRECT(B$1&"!$a1:$a10000")=汇总!$A99),COUNTIF(INDIRECT(B$1&"!$a1:$a10000"),汇总!$A99)),B98)} -> 319.27263 | C99: {=IFERROR(INDEX(_xlfn._xlws.FILTER(INDIRECT(C$1&"!$E1:$E10000"),INDIRECT(C$1&"!$a1:$a10000")=汇总!$A99),COUNTIF(INDIRECT(C$1&"!$a1:$a10000"),汇总!$A99)),C98)} -> 2141.7865 | D99: {=IFERROR(INDEX(_xlfn._xlws.FILTER(INDIRECT(D$1&"!$E1:$E10000"),INDIRECT(D$1&"!$a1:$a10000")=汇总!$A99),COUNTIF(INDIRECT(D$1&"!$a1:$a10000"),汇总!$A99)),D98)} -> 80.46049 | E99: {=IFERROR(INDEX(_xlfn._xlws.FILTER(INDIRECT(E$1&"!$E1:$E10000"),INDIRECT(E$1&"!$a1:$a10000")=汇总!$A99),COUNTIF(INDIRECT(E$1&"!$a1:$a10000"),汇总!$A99)),E98)} -> 25.88085 | F99: {=IFERROR(INDEX(_xlfn._xlws.FILTER(INDIRECT(F$1&"!$E1:$E10000"),INDIRECT(F$1&"!$a1:$a10000")=汇总!$A99),COUNTIF(INDIRECT(F$1&"!$a1:$a10000"),汇总!$A99)),F98)} -> 7350 | G99: {=IFERROR(INDEX(_xlfn._xlws.FILTER(INDIRECT(G$1&"!$E1:$E10000"),INDIRECT(G$1&"!$a1:$a10000")=汇总!$A99),COUNTIF(INDIRECT(G$1&"!$a1:$a10000"),汇总!$A99)),G98)} -> 6771.4 | H99: {=IFERROR(INDEX(_xlfn._xlws.FILTER(INDIRECT(H$1&"!$E1:$E10000"),INDIRECT(H$1&"!$a1:$a10000")=汇总!$A99),COUNTIF(INDIRECT(H$1&"!$a1:$a10000"),汇总!$A99)),H98)} -> 431.92997 | I99: {=IFERROR(INDEX(_xlfn._xlws.FILTER(INDIRECT(I$1&"!$E1:$E10000"),INDIRECT(I$1&"!$a1:$a10000")=汇总!$A99),COUNTIF(INDIRECT(I$1&"!$a1:$a10000"),汇总!$A99)),I98)} -> 171.20811 | ... T99: {=IFERROR(INDEX(_xlfn._xlws.FILTER(INDIRECT(T$1&"!$E1:$E10000"),INDIRECT(T$1&"!$a1:$a10000")=汇总!$A99),COUNTIF(INDIRECT(T$1&"!$a1:$a10000"),汇总!$A99)),T98)} -> 0
A100: =+A99+1 -> 46121 | B100: {=IFERROR(INDEX(_xlfn._xlws.FILTER(INDIRECT(B$1&"!$E1:$E10000"),INDIRECT(B$1&"!$a1:$a10000")=汇总!$A100),COUNTIF(INDIRECT(B$1&"!$a1:$a10000"),汇总!$A100)),B99)} -> 1059.2726 | C100: {=IFERROR(INDEX(_xlfn._xlws.FILTER(INDIRECT(C$1&"!$E1:$E10000"),INDIRECT(C$1&"!$a1:$a10000")=汇总!$A100),COUNTIF(INDIRECT(C$1&"!$a1:$a10000"),汇总!$A100)),C99)} -> 1141.7865 | D100: {=IFERROR(INDEX(_xlfn._xlws.FILTER(INDIRECT(D$1&"!$E1:$E10000"),INDIRECT(D$1&"!$a1:$a10000")=汇总!$A100),COUNTIF(INDIRECT(D$1&"!$a1:$a10000"),汇总!$A100)),D99)} -> 2080.4605 | E100: {=IFERROR(INDEX(_xlfn._xlws.FILTER(INDIRECT(E$1&"!$E1:$E10000"),INDIRECT(E$1&"!$a1:$a10000")=汇总!$A100),COUNTIF(INDIRECT(E$1&"!$a1:$a10000"),汇总!$A100)),E99)} -> 25.88085 | F100: {=IFERROR(INDEX(_xlfn._xlws.FILTER(INDIRECT(F$1&"!$E1:$E10000"),INDIRECT(F$1&"!$a1:$a10000")=汇总!$A100),COUNTIF(INDIRECT(F$1&"!$a1:$a10000"),汇总!$A100)),F99)} -> 7350 | G100: {=IFERROR(INDEX(_xlfn._xlws.FILTER(INDIRECT(G$1&"!$E1:$E10000"),INDIRECT(G$1&"!$a1:$a10000")=汇总!$A100),COUNTIF(INDIRECT(G$1&"!$a1:$a10000"),汇总!$A100)),G99)} -> 6771.4 | H100: {=IFERROR(INDEX(_xlfn._xlws.FILTER(INDIRECT(H$1&"!$E1:$E10000"),INDIRECT(H$1&"!$a1:$a10000")=汇总!$A100),COUNTIF(INDIRECT(H$1&"!$a1:$a10000"),汇总!$A100)),H99)} -> 431.92997 | I100: {=IFERROR(INDEX(_xlfn._xlws.FILTER(INDIRECT(I$1&"!$E1:$E10000"),INDIRECT(I$1&"!$a1:$a10000")=汇总!$A100),COUNTIF(INDIRECT(I$1&"!$a1:$a10000"),汇总!$A100)),I99)} -> 171.20811 | ... T100: {=IFERROR(INDEX(_xlfn._xlws.FILTER(INDIRECT(T$1&"!$E1:$E10000"),INDIRECT(T$1&"!$a1:$a10000")=汇总!$A100),COUNTIF(INDIRECT(T$1&"!$a1:$a10000"),汇总!$A100)),T99)} -> 0
A101: =+A100+1 -> 46122 | B101: {=IFERROR(INDEX(_xlfn._xlws.FILTER(INDIRECT(B$1&"!$E1:$E10000"),INDIRECT(B$1&"!$a1:$a10000")=汇总!$A101),COUNTIF(INDIRECT(B$1&"!$a1:$a10000"),汇总!$A101)),B100)} -> 59.272627 | C101: {=IFERROR(INDEX(_xlfn._xlws.FILTER(INDIRECT(C$1&"!$E1:$E10000"),INDIRECT(C$1&"!$a1:$a10000")=汇总!$A101),COUNTIF(INDIRECT(C$1&"!$a1:$a10000"),汇总!$A101)),C100)} -> 1074.962 | D101: {=IFERROR(INDEX(_xlfn._xlws.FILTER(INDIRECT(D$1&"!$E1:$E10000"),INDIRECT(D$1&"!$a1:$a10000")=汇总!$A101),COUNTIF(INDIRECT(D$1&"!$a1:$a10000"),汇总!$A101)),D100)} -> 1972.5585 | E101: {=IFERROR(INDEX(_xlfn._xlws.FILTER(INDIRECT(E$1&"!$E1:$E10000"),INDIRECT(E$1&"!$a1:$a10000")=汇总!$A101),COUNTIF(INDIRECT(E$1&"!$a1:$a10000"),汇总!$A101)),E100)} -> 1748.4758 | F101: {=IFERROR(INDEX(_xlfn._xlws.FILTER(INDIRECT(F$1&"!$E1:$E10000"),INDIRECT(F$1&"!$a1:$a10000")=汇总!$A101),COUNTIF(INDIRECT(F$1&"!$a1:$a10000"),汇总!$A101)),F100)} -> 7350 | G101: {=IFERROR(INDEX(_xlfn._xlws.FILTER(INDIRECT(G$1&"!$E1:$E10000"),INDIRECT(G$1&"!$a1:$a10000")=汇总!$A101),COUNTIF(INDIRECT(G$1&"!$a1:$a10000"),汇总!$A101)),G100)} -> 6771.4 | H101: {=IFERROR(INDEX(_xlfn._xlws.FILTER(INDIRECT(H$1&"!$E1:$E10000"),INDIRECT(H$1&"!$a1:$a10000")=汇总!$A101),COUNTIF(INDIRECT(H$1&"!$a1:$a10000"),汇总!$A101)),H100)} -> 119 | I101: {=IFERROR(INDEX(_xlfn._xlws.FILTER(INDIRECT(I$1&"!$E1:$E10000"),INDIRECT(I$1&"!$a1:$a10000")=汇总!$A101),COUNTIF(INDIRECT(I$1&"!$a1:$a10000"),汇总!$A101)),I100)} -> 17.531309 | ... T101: {=IFERROR(INDEX(_xlfn._xlws.FILTER(INDIRECT(T$1&"!$E1:$E10000"),INDIRECT(T$1&"!$a1:$a10000")=汇总!$A101),COUNTIF(INDIRECT(T$1&"!$a1:$a10000"),汇总!$A101)),T100)} -> 0
A102: =+A101+1 -> 46123 | B102: {=IFERROR(INDEX(_xlfn._xlws.FILTER(INDIRECT(B$1&"!$E1:$E10000"),INDIRECT(B$1&"!$a1:$a10000")=汇总!$A102),COUNTIF(INDIRECT(B$1&"!$a1:$a10000"),汇总!$A102)),B101)} -> 59.272627 | C102: {=IFERROR(INDEX(_xlfn._xlws.FILTER(INDIRECT(C$1&"!$E1:$E10000"),INDIRECT(C$1&"!$a1:$a10000")=汇总!$A102),COUNTIF(INDIRECT(C$1&"!$a1:$a10000"),汇总!$A102)),C101)} -> 1074.962 | D102: {=IFERROR(INDEX(_xlfn._xlws.FILTER(INDIRECT(D$1&"!$E1:$E10000"),INDIRECT(D$1&"!$a1:$a10000")=汇总!$A102),COUNTIF(INDIRECT(D$1&"!$a1:$a10000"),汇总!$A102)),D101)} -> 1972.5585 | E102: {=IFERROR(INDEX(_xlfn._xlws.FILTER(INDIRECT(E$1&"!$E1:$E10000"),INDIRECT(E$1&"!$a1:$a10000")=汇总!$A102),COUNTIF(INDIRECT(E$1&"!$a1:$a10000"),汇总!$A102)),E101)} -> 1748.4758 | F102: {=IFERROR(INDEX(_xlfn._xlws.FILTER(INDIRECT(F$1&"!$E1:$E10000"),INDIRECT(F$1&"!$a1:$a10000")=汇总!$A102),COUNTIF(INDIRECT(F$1&"!$a1:$a10000"),汇总!$A102)),F101)} -> 7350 | G102: {=IFERROR(INDEX(_xlfn._xlws.FILTER(INDIRECT(G$1&"!$E1:$E10000"),INDIRECT(G$1&"!$a1:$a10000")=汇总!$A102),COUNTIF(INDIRECT(G$1&"!$a1:$a10000"),汇总!$A102)),G101)} -> 6771.4 | H102: {=IFERROR(INDEX(_xlfn._xlws.FILTER(INDIRECT(H$1&"!$E1:$E10000"),INDIRECT(H$1&"!$a1:$a10000")=汇总!$A102),COUNTIF(INDIRECT(H$1&"!$a1:$a10000"),汇总!$A102)),H101)} -> 119 | I102: {=IFERROR(INDEX(_xlfn._xlws.FILTER(INDIRECT(I$1&"!$E1:$E10000"),INDIRECT(I$1&"!$a1:$a10000")=汇总!$A102),COUNTIF(INDIRECT(I$1&"!$a1:$a10000"),汇总!$A102)),I101)} -> 17.531309 | ... T102: {=IFERROR(INDEX(_xlfn._xlws.FILTER(INDIRECT(T$1&"!$E1:$E10000"),INDIRECT(T$1&"!$a1:$a10000")=汇总!$A102),COUNTIF(INDIRECT(T$1&"!$a1:$a10000"),汇总!$A102)),T101)} -> 0
A103: =+A102+1 -> 46124 | B103: {=IFERROR(INDEX(_xlfn._xlws.FILTER(INDIRECT(B$1&"!$E1:$E10000"),INDIRECT(B$1&"!$a1:$a10000")=汇总!$A103),COUNTIF(INDIRECT(B$1&"!$a1:$a10000"),汇总!$A103)),B102)} -> 59.272627 | C103: {=IFERROR(INDEX(_xlfn._xlws.FILTER(INDIRECT(C$1&"!$E1:$E10000"),INDIRECT(C$1&"!$a1:$a10000")=汇总!$A103),COUNTIF(INDIRECT(C$1&"!$a1:$a10000"),汇总!$A103)),C102)} -> 1074.962 | D103: {=IFERROR(INDEX(_xlfn._xlws.FILTER(INDIRECT(D$1&"!$E1:$E10000"),INDIRECT(D$1&"!$a1:$a10000")=汇总!$A103),COUNTIF(INDIRECT(D$1&"!$a1:$a10000"),汇总!$A103)),D102)} -> 1972.5585 | E103: {=IFERROR(INDEX(_xlfn._xlws.FILTER(INDIRECT(E$1&"!$E1:$E10000"),INDIRECT(E$1&"!$a1:$a10000")=汇总!$A103),COUNTIF(INDIRECT(E$1&"!$a1:$a10000"),汇总!$A103)),E102)} -> 1748.4758 | F103: {=IFERROR(INDEX(_xlfn._xlws.FILTER(INDIRECT(F$1&"!$E1:$E10000"),INDIRECT(F$1&"!$a1:$a10000")=汇总!$A103),COUNTIF(INDIRECT(F$1&"!$a1:$a10000"),汇总!$A103)),F102)} -> 7350 | G103: {=IFERROR(INDEX(_xlfn._xlws.FILTER(INDIRECT(G$1&"!$E1:$E10000"),INDIRECT(G$1&"!$a1:$a10000")=汇总!$A103),COUNTIF(INDIRECT(G$1&"!$a1:$a10000"),汇总!$A103)),G102)} -> 6771.4 | H103: {=IFERROR(INDEX(_xlfn._xlws.FILTER(INDIRECT(H$1&"!$E1:$E10000"),INDIRECT(H$1&"!$a1:$a10000")=汇总!$A103),COUNTIF(INDIRECT(H$1&"!$a1:$a10000"),汇总!$A103)),H102)} -> 119 | I103: {=IFERROR(INDEX(_xlfn._xlws.FILTER(INDIRECT(I$1&"!$E1:$E10000"),INDIRECT(I$1&"!$a1:$a10000")=汇总!$A103),COUNTIF(INDIRECT(I$1&"!$a1:$a10000"),汇总!$A103)),I102)} -> 17.531309 | ... T103: {=IFERROR(INDEX(_xlfn._xlws.FILTER(INDIRECT(T$1&"!$E1:$E10000"),INDIRECT(T$1&"!$a1:$a10000")=汇总!$A103),COUNTIF(INDIRECT(T$1&"!$a1:$a10000"),汇总!$A103)),T102)} -> 0
A104: =+A103+1 -> 46125 | B104: {=IFERROR(INDEX(_xlfn._xlws.FILTER(INDIRECT(B$1&"!$E1:$E10000"),INDIRECT(B$1&"!$a1:$a10000")=汇总!$A104),COUNTIF(INDIRECT(B$1&"!$a1:$a10000"),汇总!$A104)),B103)} -> 662 | C104: {=IFERROR(INDEX(_xlfn._xlws.FILTER(INDIRECT(C$1&"!$E1:$E10000"),INDIRECT(C$1&"!$a1:$a10000")=汇总!$A104),COUNTIF(INDIRECT(C$1&"!$a1:$a10000"),汇总!$A104)),C103)} -> 1074.962 | D104: {=IFERROR(INDEX(_xlfn._xlws.FILTER(INDIRECT(D$1&"!$E1:$E10000"),INDIRECT(D$1&"!$a1:$a10000")=汇总!$A104),COUNTIF(INDIRECT(D$1&"!$a1:$a10000"),汇总!$A104)),D103)} -> 1679.7385 | E104: {=IFERROR(INDEX(_xlfn._xlws.FILTER(INDIRECT(E$1&"!$E1:$E10000"),INDIRECT(E$1&"!$a1:$a10000")=汇总!$A104),COUNTIF(INDIRECT(E$1&"!$a1:$a10000"),汇总!$A104)),E103)} -> 1748.4758 | F104: {=IFERROR(INDEX(_xlfn._xlws.FILTER(INDIRECT(F$1&"!$E1:$E10000"),INDIRECT(F$1&"!$a1:$a10000")=汇总!$A104),COUNTIF(INDIRECT(F$1&"!$a1:$a10000"),汇总!$A104)),F103)} -> 7350 | G104: {=IFERROR(INDEX(_xlfn._xlws.FILTER(INDIRECT(G$1&"!$E1:$E10000"),INDIRECT(G$1&"!$a1:$a10000")=汇总!$A104),COUNTIF(INDIRECT(G$1&"!$a1:$a10000"),汇总!$A104)),G103)} -> 7703 | H104: {=IFERROR(INDEX(_xlfn._xlws.FILTER(INDIRECT(H$1&"!$E1:$E10000"),INDIRECT(H$1&"!$a1:$a10000")=汇总!$A104),COUNTIF(INDIRECT(H$1&"!$a1:$a10000"),汇总!$A104)),H103)} -> 219 | I104: {=IFERROR(INDEX(_xlfn._xlws.FILTER(INDIRECT(I$1&"!$E1:$E10000"),INDIRECT(I$1&"!$a1:$a10000")=汇总!$A104),COUNTIF(INDIRECT(I$1&"!$a1:$a10000"),汇总!$A104)),I103)} -> 17.531309 | ... T104: {=IFERROR(INDEX(_xlfn._xlws.FILTER(INDIRECT(T$1&"!$E1:$E10000"),INDIRECT(T$1&"!$a1:$a10000")=汇总!$A104),COUNTIF(INDIRECT(T$1&"!$a1:$a10000"),汇总!$A104)),T103)} -> 0
A105: =+A104+1 -> 46126 | B105: {=IFERROR(INDEX(_xlfn._xlws.FILTER(INDIRECT(B$1&"!$E1:$E10000"),INDIRECT(B$1&"!$a1:$a10000")=汇总!$A105),COUNTIF(INDIRECT(B$1&"!$a1:$a10000"),汇总!$A105)),B104)} -> 360.1206 | C105: {=IFERROR(INDEX(_xlfn._xlws.FILTER(INDIRECT(C$1&"!$E1:$E10000"),INDIRECT(C$1&"!$a1:$a10000")=汇总!$A105),COUNTIF(INDIRECT(C$1&"!$a1:$a10000"),汇总!$A105)),C104)} -> 1074.962 | D105: {=IFERROR(INDEX(_xlfn._xlws.FILTER(INDIRECT(D$1&"!$E1:$E10000"),INDIRECT(D$1&"!$a1:$a10000")=汇总!$A105),COUNTIF(INDIRECT(D$1&"!$a1:$a10000"),汇总!$A105)),D104)} -> 2018.4385 | E105: {=IFERROR(INDEX(_xlfn._xlws.FILTER(INDIRECT(E$1&"!$E1:$E10000"),INDIRECT(E$1&"!$a1:$a10000")=汇总!$A105),COUNTIF(INDIRECT(E$1&"!$a1:$a10000"),汇总!$A105)),E104)} -> 679.61835 | F105: {=IFERROR(INDEX(_xlfn._xlws.FILTER(INDIRECT(F$1&"!$E1:$E10000"),INDIRECT(F$1&"!$a1:$a10000")=汇总!$A105),COUNTIF(INDIRECT(F$1&"!$a1:$a10000"),汇总!$A105)),F104)} -> 7350 | G105: {=IFERROR(INDEX(_xlfn._xlws.FILTER(INDIRECT(G$1&"!$E1:$E10000"),INDIRECT(G$1&"!$a1:$a10000")=汇总!$A105),COUNTIF(INDIRECT(G$1&"!$a1:$a10000"),汇总!$A105)),G104)} -> 7703 | H105: {=IFERROR(INDEX(_xlfn._xlws.FILTER(INDIRECT(H$1&"!$E1:$E10000"),INDIRECT(H$1&"!$a1:$a10000")=汇总!$A105),COUNTIF(INDIRECT(H$1&"!$a1:$a10000"),汇总!$A105)),H104)} -> 219 | I105: {=IFERROR(INDEX(_xlfn._xlws.FILTER(INDIRECT(I$1&"!$E1:$E10000"),INDIRECT(I$1&"!$a1:$a10000")=汇总!$A105),COUNTIF(INDIRECT(I$1&"!$a1:$a10000"),汇总!$A105)),I104)} -> 17.531309 | ... T105: {=IFERROR(INDEX(_xlfn._xlws.FILTER(INDIRECT(T$1&"!$E1:$E10000"),INDIRECT(T$1&"!$a1:$a10000")=汇总!$A105),COUNTIF(INDIRECT(T$1&"!$a1:$a10000"),汇总!$A105)),T104)} -> 0
A106: =+A105+1 -> 46127 | B106: {=IFERROR(INDEX(_xlfn._xlws.FILTER(INDIRECT(B$1&"!$E1:$E10000"),INDIRECT(B$1&"!$a1:$a10000")=汇总!$A106),COUNTIF(INDIRECT(B$1&"!$a1:$a10000"),汇总!$A106)),B105)} -> 748.1206 | C106: {=IFERROR(INDEX(_xlfn._xlws.FILTER(INDIRECT(C$1&"!$E1:$E10000"),INDIRECT(C$1&"!$a1:$a10000")=汇总!$A106),COUNTIF(INDIRECT(C$1&"!$a1:$a10000"),汇总!$A106)),C105)} -> 1357 | D106: {=IFERROR(INDEX(_xlfn._xlws.FILTER(INDIRECT(D$1&"!$E1:$E10000"),INDIRECT(D$1&"!$a1:$a10000")=汇总!$A106),COUNTIF(INDIRECT(D$1&"!$a1:$a10000"),汇总!$A106)),D105)} -> 62.72031 | E106: {=IFERROR(INDEX(_xlfn._xlws.FILTER(INDIRECT(E$1&"!$E1:$E10000"),INDIRECT(E$1&"!$a1:$a10000")=汇总!$A106),COUNTIF(INDIRECT(E$1&"!$a1:$a10000"),汇总!$A106)),E105)} -> 910.01835 | F106: {=IFERROR(INDEX(_xlfn._xlws.FILTER(INDIRECT(F$1&"!$E1:$E10000"),INDIRECT(F$1&"!$a1:$a10000")=汇总!$A106),COUNTIF(INDIRECT(F$1&"!$a1:$a10000"),汇总!$A106)),F105)} -> 9096 | G106: {=IFERROR(INDEX(_xlfn._xlws.FILTER(INDIRECT(G$1&"!$E1:$E10000"),INDIRECT(G$1&"!$a1:$a10000")=汇总!$A106),COUNTIF(INDIRECT(G$1&"!$a1:$a10000"),汇总!$A106)),G105)} -> 8780.4 | H106: {=IFERROR(INDEX(_xlfn._xlws.FILTER(INDIRECT(H$1&"!$E1:$E10000"),INDIRECT(H$1&"!$a1:$a10000")=汇总!$A106),COUNTIF(INDIRECT(H$1&"!$a1:$a10000"),汇总!$A106)),H105)} -> 219 | I106: {=IFERROR(INDEX(_xlfn._xlws.FILTER(INDIRECT(I$1&"!$E1:$E10000"),INDIRECT(I$1&"!$a1:$a10000")=汇总!$A106),COUNTIF(INDIRECT(I$1&"!$a1:$a10000"),汇总!$A106)),I105)} -> 17.531309 | ... T106: {=IFERROR(INDEX(_xlfn._xlws.FILTER(INDIRECT(T$1&"!$E1:$E10000"),INDIRECT(T$1&"!$a1:$a10000")=汇总!$A106),COUNTIF(INDIRECT(T$1&"!$a1:$a10000"),汇总!$A106)),T105)} -> 0
A107: =+A106+1 -> 46128 | B107: {=IFERROR(INDEX(_xlfn._xlws.FILTER(INDIRECT(B$1&"!$E1:$E10000"),INDIRECT(B$1&"!$a1:$a10000")=汇总!$A107),COUNTIF(INDIRECT(B$1&"!$a1:$a10000"),汇总!$A107)),B106)} -> 748.1206 | C107: {=IFERROR(INDEX(_xlfn._xlws.FILTER(INDIRECT(C$1&"!$E1:$E10000"),INDIRECT(C$1&"!$a1:$a10000")=汇总!$A107),COUNTIF(INDIRECT(C$1&"!$a1:$a10000"),汇总!$A107)),C106)} -> 1662 | D107: {=IFERROR(INDEX(_xlfn._xlws.FILTER(INDIRECT(D$1&"!$E1:$E10000"),INDIRECT(D$1&"!$a1:$a10000")=汇总!$A107),COUNTIF(INDIRECT(D$1&"!$a1:$a10000"),汇总!$A107)),D106)} -> 62.72031 | E107: {=IFERROR(INDEX(_xlfn._xlws.FILTER(INDIRECT(E$1&"!$E1:$E10000"),INDIRECT(E$1&"!$a1:$a10000")=汇总!$A107),COUNTIF(INDIRECT(E$1&"!$a1:$a10000"),汇总!$A107)),E106)} -> 913.00835 | F107: {=IFERROR(INDEX(_xlfn._xlws.FILTER(INDIRECT(F$1&"!$E1:$E10000"),INDIRECT(F$1&"!$a1:$a10000")=汇总!$A107),COUNTIF(INDIRECT(F$1&"!$a1:$a10000"),汇总!$A107)),F106)} -> 11482 | G107: {=IFERROR(INDEX(_xlfn._xlws.FILTER(INDIRECT(G$1&"!$E1:$E10000"),INDIRECT(G$1&"!$a1:$a10000")=汇总!$A107),COUNTIF(INDIRECT(G$1&"!$a1:$a10000"),汇总!$A107)),G106)} -> 8047.4 | H107: {=IFERROR(INDEX(_xlfn._xlws.FILTER(INDIRECT(H$1&"!$E1:$E10000"),INDIRECT(H$1&"!$a1:$a10000")=汇总!$A107),COUNTIF(INDIRECT(H$1&"!$a1:$a10000"),汇总!$A107)),H106)} -> 219 | I107: {=IFERROR(INDEX(_xlfn._xlws.FILTER(INDIRECT(I$1&"!$E1:$E10000"),INDIRECT(I$1&"!$a1:$a10000")=汇总!$A107),COUNTIF(INDIRECT(I$1&"!$a1:$a10000"),汇总!$A107)),I106)} -> 17.531309 | ... T107: {=IFERROR(INDEX(_xlfn._xlws.FILTER(INDIRECT(T$1&"!$E1:$E10000"),INDIRECT(T$1&"!$a1:$a10000")=汇总!$A107),COUNTIF(INDIRECT(T$1&"!$a1:$a10000"),汇总!$A107)),T106)} -> 0
A108: =+A107+1 -> 46129 | B108: {=IFERROR(INDEX(_xlfn._xlws.FILTER(INDIRECT(B$1&"!$E1:$E10000"),INDIRECT(B$1&"!$a1:$a10000")=汇总!$A108),COUNTIF(INDIRECT(B$1&"!$a1:$a10000"),汇总!$A108)),B107)} -> 168.1206 | C108: {=IFERROR(INDEX(_xlfn._xlws.FILTER(INDIRECT(C$1&"!$E1:$E10000"),INDIRECT(C$1&"!$a1:$a10000")=汇总!$A108),COUNTIF(INDIRECT(C$1&"!$a1:$a10000"),汇总!$A108)),C107)} -> 2172 | D108: {=IFERROR(INDEX(_xlfn._xlws.FILTER(INDIRECT(D$1&"!$E1:$E10000"),INDIRECT(D$1&"!$a1:$a10000")=汇总!$A108),COUNTIF(INDIRECT(D$1&"!$a1:$a10000"),汇总!$A108)),D107)} -> 3566.7203 | E108: {=IFERROR(INDEX(_xlfn._xlws.FILTER(INDIRECT(E$1&"!$E1:$E10000"),INDIRECT(E$1&"!$a1:$a10000")=汇总!$A108),COUNTIF(INDIRECT(E$1&"!$a1:$a10000"),汇总!$A108)),E107)} -> 916.29835 | F108: {=IFERROR(INDEX(_xlfn._xlws.FILTER(INDIRECT(F$1&"!$E1:$E10000"),INDIRECT(F$1&"!$a1:$a10000")=汇总!$A108),COUNTIF(INDIRECT(F$1&"!$a1:$a10000"),汇总!$A108)),F107)} -> 11482 | G108: {=IFERROR(INDEX(_xlfn._xlws.FILTER(INDIRECT(G$1&"!$E1:$E10000"),INDIRECT(G$1&"!$a1:$a10000")=汇总!$A108),COUNTIF(INDIRECT(G$1&"!$a1:$a10000"),汇总!$A108)),G107)} -> 5293.4 | H108: {=IFERROR(INDEX(_xlfn._xlws.FILTER(INDIRECT(H$1&"!$E1:$E10000"),INDIRECT(H$1&"!$a1:$a10000")=汇总!$A108),COUNTIF(INDIRECT(H$1&"!$a1:$a10000"),汇总!$A108)),H107)} -> 419 | I108: {=IFERROR(INDEX(_xlfn._xlws.FILTER(INDIRECT(I$1&"!$E1:$E10000"),INDIRECT(I$1&"!$a1:$a10000")=汇总!$A108),COUNTIF(INDIRECT(I$1&"!$a1:$a10000"),汇总!$A108)),I107)} -> 17.531309 | ... T108: {=IFERROR(INDEX(_xlfn._xlws.FILTER(INDIRECT(T$1&"!$E1:$E10000"),INDIRECT(T$1&"!$a1:$a10000")=汇总!$A108),COUNTIF(INDIRECT(T$1&"!$a1:$a10000"),汇总!$A108)),T107)} -> 0
A109: =+A108+1 -> 46130 | B109: {=IFERROR(INDEX(_xlfn._xlws.FILTER(INDIRECT(B$1&"!$E1:$E10000"),INDIRECT(B$1&"!$a1:$a10000")=汇总!$A109),COUNTIF(INDIRECT(B$1&"!$a1:$a10000"),汇总!$A109)),B108)} -> 168.1206 | C109: {=IFERROR(INDEX(_xlfn._xlws.FILTER(INDIRECT(C$1&"!$E1:$E10000"),INDIRECT(C$1&"!$a1:$a10000")=汇总!$A109),COUNTIF(INDIRECT(C$1&"!$a1:$a10000"),汇总!$A109)),C108)} -> 2172 | D109: {=IFERROR(INDEX(_xlfn._xlws.FILTER(INDIRECT(D$1&"!$E1:$E10000"),INDIRECT(D$1&"!$a1:$a10000")=汇总!$A109),COUNTIF(INDIRECT(D$1&"!$a1:$a10000"),汇总!$A109)),D108)} -> 3566.7203 | E109: {=IFERROR(INDEX(_xlfn._xlws.FILTER(INDIRECT(E$1&"!$E1:$E10000"),INDIRECT(E$1&"!$a1:$a10000")=汇总!$A109),COUNTIF(INDIRECT(E$1&"!$a1:$a10000"),汇总!$A109)),E108)} -> 916.29835 | F109: {=IFERROR(INDEX(_xlfn._xlws.FILTER(INDIRECT(F$1&"!$E1:$E10000"),INDIRECT(F$1&"!$a1:$a10000")=汇总!$A109),COUNTIF(INDIRECT(F$1&"!$a1:$a10000"),汇总!$A109)),F108)} -> 11482 | G109: {=IFERROR(INDEX(_xlfn._xlws.FILTER(INDIRECT(G$1&"!$E1:$E10000"),INDIRECT(G$1&"!$a1:$a10000")=汇总!$A109),COUNTIF(INDIRECT(G$1&"!$a1:$a10000"),汇总!$A109)),G108)} -> 5293.4 | H109: {=IFERROR(INDEX(_xlfn._xlws.FILTER(INDIRECT(H$1&"!$E1:$E10000"),INDIRECT(H$1&"!$a1:$a10000")=汇总!$A109),COUNTIF(INDIRECT(H$1&"!$a1:$a10000"),汇总!$A109)),H108)} -> 419 | I109: {=IFERROR(INDEX(_xlfn._xlws.FILTER(INDIRECT(I$1&"!$E1:$E10000"),INDIRECT(I$1&"!$a1:$a10000")=汇总!$A109),COUNTIF(INDIRECT(I$1&"!$a1:$a10000"),汇总!$A109)),I108)} -> 17.531309 | ... T109: {=IFERROR(INDEX(_xlfn._xlws.FILTER(INDIRECT(T$1&"!$E1:$E10000"),INDIRECT(T$1&"!$a1:$a10000")=汇总!$A109),COUNTIF(INDIRECT(T$1&"!$a1:$a10000"),汇总!$A109)),T108)} -> 0
... A168: =+A167+1 -> 46189 | B168: {=IFERROR(INDEX(_xlfn._xlws.FILTER(INDIRECT(B$1&"!$E1:$E10000"),INDIRECT(B$1&"!$a1:$a10000")=汇总!$A168),COUNTIF(INDIRECT(B$1&"!$a1:$a10000"),汇总!$A168)),B167)} -> 78.592656 | C168: {=IFERROR(INDEX(_xlfn._xlws.FILTER(INDIRECT(C$1&"!$E1:$E10000"),INDIRECT(C$1&"!$a1:$a10000")=汇总!$A168),COUNTIF(INDIRECT(C$1&"!$a1:$a10000"),汇总!$A168)),C167)} -> 2090 | D168: {=IFERROR(INDEX(_xlfn._xlws.FILTER(INDIRECT(D$1&"!$E1:$E10000"),INDIRECT(D$1&"!$a1:$a10000")=汇总!$A168),COUNTIF(INDIRECT(D$1&"!$a1:$a10000"),汇总!$A168)),D167)} -> 487.84341 | E168: {=IFERROR(INDEX(_xlfn._xlws.FILTER(INDIRECT(E$1&"!$E1:$E10000"),INDIRECT(E$1&"!$a1:$a10000")=汇总!$A168),COUNTIF(INDIRECT(E$1&"!$a1:$a10000"),汇总!$A168)),E167)} -> -2107.3149 | F168: {=IFERROR(INDEX(_xlfn._xlws.FILTER(INDIRECT(F$1&"!$E1:$E10000"),INDIRECT(F$1&"!$a1:$a10000")=汇总!$A168),COUNTIF(INDIRECT(F$1&"!$a1:$a10000"),汇总!$A168)),F167)} -> 2186.6524 | G168: {=IFERROR(INDEX(_xlfn._xlws.FILTER(INDIRECT(G$1&"!$E1:$E10000"),INDIRECT(G$1&"!$a1:$a10000")=汇总!$A168),COUNTIF(INDIRECT(G$1&"!$a1:$a10000"),汇总!$A168)),G167)} -> 9558.0087 | H168: {=IFERROR(INDEX(_xlfn._xlws.FILTER(INDIRECT(H$1&"!$E1:$E10000"),INDIRECT(H$1&"!$a1:$a10000")=汇总!$A168),COUNTIF(INDIRECT(H$1&"!$a1:$a10000"),汇总!$A168)),H167)} -> -83.365251 | I168: {=IFERROR(INDEX(_xlfn._xlws.FILTER(INDIRECT(I$1&"!$E1:$E10000"),INDIRECT(I$1&"!$a1:$a10000")=汇总!$A168),COUNTIF(INDIRECT(I$1&"!$a1:$a10000"),汇总!$A168)),I167)} -> 14.342121 | ... T168: {=IFERROR(INDEX(_xlfn._xlws.FILTER(INDIRECT(T$1&"!$E1:$E10000"),INDIRECT(T$1&"!$a1:$a10000")=汇总!$A168),COUNTIF(INDIRECT(T$1&"!$a1:$a10000"),汇总!$A168)),T167)} -> 9874.43

Sheet 元康盛景20号
A2: 日期 | B2: 现金流类型 | C2: 现金流入 | D2: 现金流出 | E2: 期末余额
A3: 46023 | E3: 619
A4: 45664 | B4: 雪球申购 | C4: 552 | E4: =E3+C4-D4 -> 1171
A5: 46029 | B5: 诚瑞1A2 | D5: 1003 | E5: 164 | F5: 鑫沅代持
A6: 46031 | B6: 新增申购 | C6: 302 | E6: =E5+C6-D6 -> 466
E7: 460
A8: 46034 | B8: 雪球申购 | C8: 121 | E8: =E7+C8-D8 -> 581
E9: =E8+C9-D9 -> 581
A10: 46034 | B10: 新增申购 | C10: 300 | E10: =E9+C10-D10 -> 881
A11: 46034 | B11: 赎回朗瑞1-5 | C11: 1100 | E11: =E10+C11-D11 -> 1981 | F11: 1-8申请 | G11: 能否提前到1-8的开放日赎回？；然后周一中午到账？
A12: 46034 | B12: 打新 | D12: 1216.5 | E12: =E11+C12-D12 -> 764.5
A13: 46035 | B13: 雪球申购 | C13: 128.4 | E13: =E12+C13-D13 -> 892.9
A14: 46035 | B14: 归还回购 | D14: 660.5 | E14: =E13+C14-D14 -> 232.4
A15: 46036 | B15: 打新 | C15: 1216 | E15: =E14+C15-D15 -> 1448.4 | F15: 涉及回来多少钱
A16: 46036 | B16: 熠然5A3 | D16: 501 | E16: =E15+C16-D16 -> 947.4 | F16: 1、熠然5A3[263739.SH]，500w，净价100元，1月14日，国泰海通 樊文娟 to 元康盛景20号 刘靖涛
A17: 46037 | B17: 云意电气 | C17: 5000 | E17: =E16+C17-D17 -> 5947.4
A18: 46037 | B18: 新增申购 | C18: 1000 | E18: =E17+C18-D18 -> 6947.4
E19: =E18+C19-D19 -> 6947.4
A20: 46037 | B20: 归还熠安02A3回购 | D20: 1247 | E20: =E19+C20-D20 -> 5700.4
A21: 46037 | B21: 回款 | C21: 170 | E21: =E20+C21-D21 -> 5870.4
E22: =E21+C22-D22 -> 5870.4
A23: 46038 | B23: 铁建051C | D23: 738 | E23: =E22+C23-D23 -> 5132.4 | F23: 铁建051C[199768.SH]，665w，111.075,1月16日，方田启航9号 to 元康盛景20号 刘靖涛
E24: 5134
A25: 46041 | B25: 支付增值税 | D25: 19 | E25: =E24+C25-D25 -> 5115
A26: 46041 | B26: 荟享244C | D26: 355 | E26: =E25+C26-D26 -> 4760 | F26: 1/19+0，荟享244C，146608.SZ，353w，净价100.159元，扬讯 出 元康盛景20号 刘靖涛
A27: 46041 | B27: 朗瑞1-5 | D27: 2600 | E27: =E26+C27-D27 -> 2160
A28: 46041 | B28: 雪球申购 | C28: 174 | E28: =E27+C28-D28 -> 2334
A29: 46041 | B29: 熠安02A3 | C29: 1112 | E29: =E28+C29-D29 -> 3446 | F29: 熠安02A3,144651.SZ,1172w,净价94.89, 1月19日，元康20号 to 扬讯
E30: 3441
A31: 46043 | B31: 雪球申购 | C31: 18 | E31: =E30+C31-D31 -> 3459
A32: 46043 | B32: 打新 | D32: 1550 | E32: =E31+C32-D32 -> 1909
E33: =E32+C33-D33 -> 1909
A34: 46044 | B34: =B5 -> 诚瑞1A2 | C34: =D5 -> 1003 | E34: =E33+C34-D34 -> 2912 | F34: 265418.SH，诚瑞1A2，1000W，净价100.15 1月22日，元康盛景20号 刘靖涛 to 新华日报基金：李旭彤2500116861
A35: 46045 | B35: 新增申购 | C35: 105 | E35: =E34+C35-D35 -> 3017
A36: 46045 | B36: 打新回款 | C36: 1550 | E36: =E35+C36-D36 -> 4567
A37: 46048 | B37: 荟享244C | C37: 353 | E37: =E36+C37-D37 -> 4920 | F37: 1/22+0，荟享244C，146608.SZ，353w，净价100.159元，元康盛景20号 刘靖涛 出 粤开证券（许逸潇）
A38: 46048 | B38: 雪球申购 | C38: 180 | E38: =E37+C38-D38 -> 5100
E39: =E38+C39-D39 -> 5100
A40: 46049 | B40: 新增申购 | C40: 100 | E40: 5207
A41: 46050 | B41: 雪球申购 | C41: 200 | E41: =E40+C41-D41 -> 5407 | F41: G铁建82C[266500.SH]，670w，102.104，1月29日，元康盛景20号 Z06308 to 鹏石启航9号 Z13506，约定号：222
...

Sheet 元康盛景26号
A2: 日期 | B2: 现金流类型 | C2: 现金流入 | D2: 现金流出 | E2: 期末余额
A3: 46023 | E3: 4182
E4: =+E3+C4-D4 -> 4182
A5: 46027 | E5: 2377
A6: 46030 | B6: 普险29B | C6: 109 | E6: =+E5+C6-D6 -> 2486
A7: 46029 | B7: 盛煜015C | C7: 550 | E7: =+E6+C7-D7 -> 3036
A8: 46029 | B8: 泓晟1号3期优先B级 | C8: 430 | E8: =+E7+C8-D8 -> 3466
A9: 46029 | B9: 五矿赎回 | D9: 3213 | E9: =+E8+C9-D9 -> 253
E10: =+E9+C10-D10 -> 253
A11: 46034 | B11: 兑付回款 | C11: 5 | E11: =+E10+C11-D11 -> 258
A12: 46035 | B12: 五矿申购 | C12: 450 | E12: =+E11+C12-D12 -> 708
A13: 46037 | B13: 兑付回款 | C13: 217 | E13: =+E12+C13-D13 -> 925 | G13: 盘下1月15日的回款，注意质押
A14: 46038 | B14: 25乐信1C | C14: 600 | E14: =+E13+C14-D14 -> 1525 | F14: 25乐信1C[264610.SH]，600w，100，1月16日，元康盛景26号 to 芜湖扬讯 Z11825
A15: 46038 | B15: 炽诚3A3 | C15: 995 | E15: =+E14+C15-D15 -> 2520 | F15: 炽诚3A3[266980.SH]，1000w，99.5，1月16日，元康盛景26号 to 芜湖扬讯 Z11825
A16: 46038 | B16: DY03优3 | C16: 1000 | E16: =+E15+C16-D16 -> 3520 | F16: DY03优3[266192.SH]，1000w，100，1月16日，元康盛景26号 to 芜湖扬讯 Z11825
E17: =+E16+C17-D17 -> 3520
A18: 46038 | B18: 熠安02A3 | D18: 570 | E18: =+E17+C18-D18 -> 2950 | F18: 熠安02A3[144651.SZ]，600w，净价94.95，1月16日，元康22 to 扬讯
E19: 2951 | F19: 熠安02A3[144651.SZ]，600w，净价94.9548，1月16日， 扬讯 to 元康26
A20: 46041 | B20: 归还回购 | D20: 2632 | E20: =+E19+C20-D20 -> 319
A21: 46042 | B21: 新增申购 | C21: 180 | E21: =+E20+C21-D21 -> 499
A22: 46044 | B22: 底层回款 | C22: 462 | E22: =+E21+C22-D22 -> 961
A23: 46045 | B23: 底层回款 | C23: 28 | E23: =+E22+C23-D23 -> 989
E24: 993
A25: 46048 | B25: 底层回款 | C25: 242 | E25: =+E24+C25-D25 -> 1235
A26: 46049 | B26: 五矿追加 | C26: 1070 | E26: =+E25+C26-D26 -> 2305
A27: 46052 | B27: 底层回款 | C27: 53 | E27: =+E26+C27-D27 -> 2358
A28: 46052 | B28: 熠然5A3 | D28: 505 | E28: 1850 | F28: 熠然5A3[263739.SH],500w,100.247净价，1-30，扬讯 to 元康盛景26号
A29: 46058 | B29: 乐信 | D29: 1500 | E29: =+E28+C29-D29 -> 350 | F29: “乐信13C”代码：500421，1500w，3.5%，2-5缴款，2-6起息，元康盛景26号
E30: 347
E31: =+E30+C31-D31 -> 347
A32: 46059 | B32: 增加回购 | C32: 2090 | E32: =+E31+C32-D32 -> 2437
A33: 46063 | B33: 五矿赎回 | D33: =300*1.076 -> 322.8 | E33: =+E32+C33-D33 -> 2114.2
A34: 46065 | B34: 小鹏B | D34: 2000 | E34: =+E33+C34-D34 -> 114.2 | F34: 小鹏5B”代码：500446，2000w，3.3%，2月12日缴款，2月13日起息，元康盛景26号
A35: 46065 | B35: 星灿5A3 | D35: 18 | E35: =+E34+C35-D35 -> 96.2 | F35: 星灿5A3,144780.SZ,18w, 净价100,2月12日，国泰海通樊文娟 to 元康盛景26号 刘靖涛
A36: 46066 | B36: 回款 | C36: 2.7 | E36: =+E35+C36-D36 -> 98.9
E37: =+E36+C37-D37 -> 98.9
A38: 46077 | B38: 回款 | C38: 727 | E38: =+E37+C38-D38 -> 825.9 | F38: 剩余539w质押中
E39: =+E38+C39-D39 -> 825.9
E40: =+E39+C40-D40 -> 825.9
A41: 46078 | B41: 25YH1A2 | C41: 794 | E41: =+E40+C41-D41 -> 1619.9 | F41: 25YH1A2[264411.SH]，净价79.218，2-25，元康盛景26号 刘靖涛3003993899 to 中信证券 xxx
...

Sheet 元康盛景28号
A2: 日期 | B2: 现金流类型 | C2: 现金流入 | D2: 现金流出 | E2: 期末余额
A3: 46023 | E3: 97
A4: 46031 | B4: 新增申购 | C4: 500 | E4: =E3+C4-D4 -> 597
E5: 579
A6: 46034 | B6: 铁建051C | D6: =365*1.11025 -> 405.24125 | E6: =E5+C6-D6 -> 173.75875 | F6: 铁建051C (199768.SH)，365w，111.025，1月12日，方田远见2号 Z06704 （方田资本陈兴宇1519091045 ）to 元康盛景28号 刘靖涛，约定号：592
A7: 46035 | B7: 五矿申购 | C7: 450 | E7: =E6+C7-D7 -> 623.75875
A8: 46035 | B8: 铁建058C | D8: =279*1.09225 -> 304.73775 | E8: =E7+C8-D8 -> 319.021 | F8: 铁建058C[260655.SH]，279w，109.225,1月13日，方田远见9号 to 元康盛景28号 刘靖涛
A9: 46035 | B9: 宝冶兑付 | C9: 50 | E9: =E8+C9-D9 -> 369.021
A10: 46037 | B10: 回款 | C10: 319 | E10: =E9+C10-D10 -> 688.021
A11: 46038 | B11: 付管理费 | D11: 54 | E11: =E10+C11-D11 -> 634.021
A12: 46038 | B12: 新增申购-爱建 | C12: 300 | E12: =E11+C12-D12 -> 934.021
E13: =E12+C13-D13 -> 934.021
A14: 46041 | B14: 支付增值税 | D14: 17.7 | E14: =E13+C14-D14 -> 916.321
A15: 46041 | B15: 卖出给苏信 | E15: =E14+C15-D15 -> 916.321 | F15: 启悦15次，146285.SZ,500w，全价103.606,1月19日，元康28号to 扬讯
B16: 启悦16次 | C16: 308.067 | E16: =E15+C16-D16 -> 1224.388 | F16: 启悦16次,146761.SZ,300w,全价102.679，1月19日，元康28号 to 扬讯
B17: 熹焱03A3 | C17: 385.94788 | E17: =E16+C17-D17 -> 1610.3359 | F17: 熹焱03A3,144237.SZ,1000w,净价38.55，1月19日，元康28号 to 扬讯
B18: 熹焱07A3 | C18: 1864.342 | E18: =E17+C18-D18 -> 3474.6779 | F18: 熹焱07A3,144671.SZ,2310w,净价80.65，1月19日，元康28号 to 扬讯
B19: 启悦15次 | C19: 518.08 | E19: =E18+C19-D19 -> 3992.7579
E20: =E19+C20-D20 -> 3992.7579
A21: 46041 | B21: 归还回购 | D21: 1762 | E21: =E20+C21-D21 -> 2230.7579 | F21: 熠安02A3归还回购
A22: 46041 | B22: 释放回款 | C22: 189 | E22: =E21+C22-D22 -> 2419.7579
A23: 46041 | B23: 云信5美好3次 | D23: =1500*1.07743 -> 1616.145 | E23: =E22+C23-D23 -> 803.61291 | F23: 5美好3次[263313.SH]，1500w面值，107.743,1月19日，云南信托QT3004414706 to 元康盛景28号 刘靖涛qt3003993899
A24: 46041 | B24: 归还回购 | D24: 498 | E24: 298
A25: 46043 | B25: G铁建82C | C25: =1960*1.01973 -> 1998.6708 | E25: =E24+C25-D25 -> 2296.6708 | F25: G铁建82C[266500.SH]，1960w，101.973，1月21日，元康盛景28号 Z06308 to xxxx
A26: 46043 | B26: 京诚153B回款 | C26: 1015 | E26: =E25+C26-D26 -> 3311.6708
A27: 46043 | B27: 归还回购-铁建 | D27: 3206 | E27: =E26+C27-D27 -> 105.6708
A28: 46044 | B28: 回购利息 | D28: 8 | E28: =E27+C28-D28 -> 97.6708
A29: 46044 | B29: 底层回款 | C29: 263 | E29: =E28+C29-D29 -> 360.6708
A30: 46044 | B30: 潍坊保函 | D30: 100 | E30: =E29+C30-D30 -> 260.6708 | F30: 已发--“26潍信2C”：500363，100w.6.5%预期，1-22一级缴款，元康盛景28号
E31: =E30+C31-D31 -> 260.6708
A32: 46044 | B32: 增加回购 | C32: 2050 | E32: =E31+C32-D32 -> 2310.6708 | F32: 押券熠然03A3，2250*60%=1350；盛煜014D，1000*70%=700
A33: 46045 | B33: 4美意6次 | D33: =470*1.08874 -> 511.7078 | E33: =E32+C33-D33 -> 1798.963 | F33: 4美意6次 (262764.SH)，470w，全价108.874，2026-1-23，国泰海通 樊文娟 to 元康盛景28号 刘靖涛
A34: 46045 | B34: 5美意3次 | D34: =350*1.06951 -> 374.3285 | E34: =E33+C34-D34 -> 1424.6345 | F34: 5美意3次[263710.SH] ,350w，全价106.951，2026-1-23，国泰海通 樊文娟 to 元康盛景28号 刘靖涛
E35: 1427
A36: 46048 | B36: 广汽3次 | D36: =400*1.22349 -> 489.396 | E36: =E35+C36-D36 -> 937.604 | F36: 广汽3次[180987.SH]，400w，122.349,1月26日，国元证券 to 元康盛景28号 刘靖涛 qt3003993899
A37: 46048 | B37: 港融6C | D37: 100 | E37: =E36+C37-D37 -> 837.604 | F37: 铁建058C[260655.SH]，279w，109.494,1月28日，元康盛景28号 刘靖涛 to 方田远见9号 Z06704，约定号：617
A38: 46050 | B38: 铁建058C | C38: =279*1.09494 -> 305.48826 | E38: =E37+C38-D38 -> 1143.0923 | F38: 铁建081C[265587.SH], 1010w, 100.381,1月28日，元康盛景28号 刘靖涛 to方田远见8号 Z06704，约定号：618
A39: 46050 | B39: 铁建081C | C39: =1300*1.00381 -> 1304.953 | E39: =E38+C39-D39 -> 2448.0453 | F39: 铁建081C[265587.SH], 290w, 100.381,1月28日，元康盛景28号 刘靖涛 to方田远见8号 Z06704，约定号：619
A40: 46050 | B40: 铁建081C | D40: =1500*1.0002 -> 1500.3 | E40: =E39+C40-D40 -> 947.74526 | F40: 铁建081C[265587.SH] ,1500w,100.02,1月28日，国泰海通 樊文娟 to 元康盛景28号 刘靖涛
E41: =E40+C41-D41 -> 947.74526
...

Sheet 元康盛景29号
T1: 剩余待补收益
A2: 日期 | B2: 现金流类型 | C2: 现金流入 | D2: 现金流出 | E2: 期末余额 | R2: 23建鑫8C需补收益 | S2: 591186 | T2: =+S2 -> 591186
A3: 46023 | E3: 234 | R3: 24兴瑞8C补 | S3: 38739.041 | T3: =+T2-S3 -> 552446.96
E4: =+E3+C4-D4 -> 234 | R4: 23中誉1C | S4: 0 | T4: =+T3-S4 -> 552446.96 | U4: 未交易
A5: 46027 | B5: 新增申购 | C5: 972 | E5: =E4+C5-D5 -> 1206 | R5: 24臻粹3C | S5: 525 | T5: =+T4-S5 -> 551921.96
A6: 46030 | B6: 新增申购 | C6: 550 | E6: =E5+C6-D6 -> 1756 | R6: 24邮盈惠兴4C | S6: 18800 | T6: =+T5-S6 -> 533121.96
A7: 46031 | B7: 申购朗瑞1-8 | D7: 1200 | E7: =E6+C7-D7 -> 556 | R7: 23工元至诚8C | S7: 331500 | T7: =+T6-S7 -> 201621.96
A8: 46031 | B8: 支付管理费 | D8: 120 | E8: =E7+C8-D8 -> 436 | R8: 25兴瑞1C | S8: 15480 | T8: =+T7-S8 -> 186141.96
E9: 436 | R9: 25橙益4C | S9: 10010 | T9: =+T8-S9 -> 176131.96
A10: 46037 | B10: 东吴申购 | C10: 5000 | E10: =E9+C10-D10 -> 5436 | R10: 24浦鑫归航8C | S10: 54000 | T10: =+T9-S10 -> 122131.96
A11: 46037 | B11: 新增申购 | C11: 536 | E11: =E10+C11-D11 -> 5972 | R11: 24建欣6C | S11: =朗瑞1_8!T29 -> 13224 | T11: =+T10-S11 -> 108907.96
A12: 46038 | B12: 申购朗瑞1-8 | D12: 500 | E12: =E11+C12-D12 -> 5472 | R12: 24橙益17C | S12: =朗瑞1_8!T30 -> 20020 | T12: =+T11-S12 -> 88887.959
E13: =E12+C13-D13 -> 5472 | R13: 25浦鑫归航1C | S13: =鹏雅120!M16 -> 88884 | T13: =+T12-S13 -> 3.9589041
E14: =E13+C14-D14 -> 5472 | G14: 待买回证券
E15: =E14+C15-D15 -> 5472 | G15: 证券名称 | H15: 合作方 | I15: 资产类别 | J15: 成本 | K15: 合作方最早买入时间 | L15: 买入规模 | M15: 持仓规模 | N15: 剩余本金 | O15: 面值 | P15: 下个本金兑付日 | Q15: 预计交易日期 | R15: 预期交易价格 | S15: 预计交易金额 | T15: 补23建鑫8C收益
A16: 46044 | B16: 申购朗瑞1-8 | D16: 2500 | E16: =E15+C16-D16 -> 2972 | G16: 23中誉1C | H16: 国泰海通 | I16: 住房抵押贷款 | J16: 0.05 | K16: 45023 | L16: 89875 | M16: 75 | N16: 0 | O16: 39.25 | P16: 46079 | Q16: 46041 | R16: =I28 -> 57.8 | S16: =R16*M16 -> 4335 | T16: =+(H28-I28)*M16 -> 210 | U16: 有可能本期本金兑付完毕
A17: 46044 | B17: 申购朗瑞1-5 | D17: 800 | E17: =E16+C17-D17 -> 2172 | G17: 24臻粹3C | H17: 国泰海通 | I17: 信用卡消费贷款 | J17: 0.045 | K17: 45523 | L17: 82500 | M17: 700 | N17: 0 | O17: 40.27 | P17: 46045 | Q17: =+Q16 -> 46041 | R17: =+M30 -> 57.1 | S17: =R17*M17 -> 39970 | T17: =+(L30-M30)*M17 -> 525 | U17: 月付，可推迟到下个月兑付前交易
A18: 46045 | B18: 新增申购 | C18: 678 | E18: =E17+C18-D18 -> 2850 | G18: 24邮盈惠兴4C | H18: 国泰海通 | I18: 信用卡消费贷款 | J18: 0.05 | K18: 45806 | L18: 40000 | M18: 40000 | N18: 440.64 | O18: 23.83 | P18: 46048 | Q18: =+Q17 -> 46041 | R18: =+Q27 -> 35.9 | S18: =R18*M18 -> 1436000 | T18: =+(P27-Q27)*M18 -> 18800 | U18: 本期必须买回
A19: 46045 | B19: 赎回 | D19: 74.6 | E19: =E18+C19-D19 -> 2775.4 | G19: 24邮盈惠兴5C | H19: 银河 | I19: 微小企业贷款 | J19: 0.05 | K19: 45862 | L19: 14000 | M19: 14000 | N19: 88.606 | O19: 40.05 | P19: 46048 | Q19: =+Q18 -> 46041 | R19: =+H40 -> 47.9555 | S19: =R19*M19 -> 671377 | U19: 本期必须买回
A20: 46045 | B20: 中航信托收款 | C20: 80.7 | E20: =E19+C20-D20 -> 2856.1 | G20: 24中誉至诚9C | H20: 国联 | I20: 信用卡消费贷款 | J20: 0.05 | K20: 45656 | L20: 6800 | M20: 6800 | N20: 68.68 | O20: 100 | P20: 46048 | Q20: =+Q19 -> 46041 | R20: =+L38 -> 106.33 | S20: =R20*M20 -> 723044
A21: 46051 | B21: 赎回朗瑞1-5 | C21: 507 | E21: =E20+C21-D21 -> 3363.1 | S21: =SUM(S17:S20) -> 2870391
E22: =+E21+C22-D22 -> 3363.1
E23: =+E22+C23-D23 -> 3363.1 | G23: 23中誉1C | H23: =XIRR(H24:H30,G24:G30) -> 0.050110647 | I23: =XIRR(I24:I30,G24:G30) -> 0.040020677 | K23: 24臻粹3C | L23: =XIRR(L24:L30,K24:K30) -> 0.045003799 | M23: =XIRR(M24:M30,K24:K30) -> 0.039925483 | O23: 24邮盈惠兴4C | P23: =XIRR(P24:P27,O24:O27) -> 0.050075492 | Q23: =XIRR(Q24:Q30,O24:O30) -> 0.040145227
E24: =+E23+C24-D24 -> 3363.1 | G24: 45023 | H24: -108 | I24: =+H24 -> -108 | K24: 45523 | L24: -111 | M24: =+L24 -> -111 | O24: 45806 | P24: -110.16 | Q24: =+P24 -> -110.16
E25: =+E24+C25-D25 -> 3363.1 | G25: 45530 | H25: 8.78 | I25: =+H25 -> 8.78 | K25: 45894 | L25: 7.55 | M25: =+L25 -> 7.55 | O25: 45866 | P25: 22.53 | Q25: =+P25 -> 22.53
A26: 46052 | B26: 鹏雅120 | D26: 300 | E26: =+E25+C26-D26 -> 3063.1 | G26: 45714 | H26: 31.21 | I26: =+H26 -> 31.21 | K26: 45923 | L26: 10.36 | M26: =+L26 -> 10.36 | O26: 45957 | P26: 53.64 | Q26: =+P26 -> 53.64
A27: 46055 | B27: 新增申购 | C27: 138 | E27: =+E26+C27-D27 -> 3201.1 | G27: 45895 | H27: 20.76 | I27: =+H27 -> 20.76 | K27: 45953 | L27: 14.23 | M27: =+L27 -> 14.23 | O27: =Q18 -> 46041 | P27: 36.37 | Q27: 35.9
A28: 46055 | B28: 赎回 | D28: 47 | E28: =+E27+C28-D28 -> 3154.1 | G28: =+Q16 -> 46041 | H28: 60.6 | I28: 57.8 | K28: 45985 | L28: 14.32 | M28: =+L28 -> 14.32 | P28: 23工元至诚8C[2389487.IB] ，1300w，126.90,1月22日，t+0，国泰海通 冉雅婷 to 外贸信托朗瑞1号8期 孟亚琪
E29: =+E28+C29-D29 -> 3154.1 | K29: 46014 | L29: 13.27 | M29: =+L29 -> 13.27 | P29: 25橙益4C[2589087.IB] ，130w，108.12,1月22日，t+0，国泰海通 冉雅婷 to 外贸信托朗瑞1号8期 孟亚琪
E30: =+E29+C30-D30 -> 3154.1 | K30: =+Q17 -> 46041 | L30: 57.85 | M30: 57.1 | P30: 25兴瑞1C[2589025.IB] ，180w，108.48,1月22日，t+0，国泰海通 冉雅婷 to 外贸信托朗瑞1号8期 孟亚琪
A31: 46056 | B31: 全景1号 | D31: 2000 | E31: =+E30+C31-D31 -> 1154.1 | P31: 24浦鑫归航8C[2489436.IB]，500w，104.29,1月22日，t+0，国泰海通 冉雅婷 to 外贸信托朗瑞1号8期 孟亚琪
E32: =+E31+C32-D32 -> 1154.1 | G32: 24臻粹3C[2489229.IB]，7w，全价57.1,1月16日，t+0，国泰海通 冉雅婷 to 外贸信托朗瑞1号8期 孟亚琪 | P32: 23工元至诚8C | Q32: =XIRR(Q33:Q34,P33:P34) -> 0.050032941 | R32: =XIRR(R33:R34,P33:P34) -> 0.039995083 | T32: 25橙益4C | U32: =XIRR(U33:U34,T33:T34) -> 0.050026986 | V32: =XIRR(V33:V34,T33:T34) -> 0.040075198
A33: 46062 | B33: 申购 | C33: 1449 | E33: 2600 | G33: 24邮盈惠兴4C[2489188.IB]，400w，全价35.9,1月16日，t+0，国泰海通 冉雅婷 to 外贸信托朗瑞1号8期 孟亚琪 | P33: 45288 | Q33: -117 | R33: =Q33 -> -117 | T33: 45772 | U33: -105 | V33: =U33 -> -105
A34: 46062 | B34: 追加鹏雅120 | D34: 1850 | E34: =+E33+C34-D34 -> 750 | G34: 24邮盈惠兴5C[2489255.IB]，140w，全价47.9555, 1月19日，t+0，银河 赵恩聪 to 外贸信托朗瑞1号8期 孟亚琪 | P34: 46044 | Q34: 129.45 | R34: 126.9 | T34: 46044 | U34: 108.89 | V34: 108.12
A35: 46065 | B35: 申购 | C35: 56 | E35: =+E34+C35-D35 -> 806 | G35: 24中誉至诚9C[2489430.IB]，68w，全价106.33,1月16日，t+0，国联 to 外贸信托朗瑞1号8期 孟亚琪（未成交） | P35: 交易份额 | Q35: 1300 | R35: =Q35 -> 1300 | T35: 交易份额 | U35: 130 | V35: =U35 -> 130
E36: 809 | G36: 24邮盈惠兴5C | H36: =XIRR(H37:H40,G37:G40) -> 0.050026587 | K36: 24中誉至诚9C | L36: =XIRR(L37:L43,K37:K43) -> 0.049963519 | P36: 交易金额 | Q36: =Q35*Q34*100 -> 16828500 | R36: =R35*R34*100 -> 16497000 | T36: 交易金额 | U36: =U35*U34*100 -> 1415570 | V36: =V35*V34*100 -> 1405560
A37: 46078 | B37: 回款 | C37: 451 | E37: =+E36+C37-D37 -> 1260 | G37: 45862 | H37: -106.22 | K37: 45656 | L37: -101 | P37: 补23建鑫8C收益 | Q37: =Q36-R36 -> 331500 | T37: 补23建鑫8C收益 | U37: =U36-V36 -> 10010
A38: 46078 | B38: 赎回 | D38: 105.8 | E38: =+E37+C38-D38 -> 1154.2 | G38: 45866 | H38: 17.02 | K38: =+Q20 -> 46041 | L38: 106.33
A39: 46079 | B39: 赎回 | D39: =9.9*1.07 -> 10.593 | E39: =+E38+C39-D39 -> 1143.607 | G39: 45957 | H39: 42.93 | P39: 25兴瑞1C | Q39: =XIRR(Q40:Q41,P40:P41) -> 0.04999927 | R39: =XIRR(R40:R41,P40:P41) -> 0.040058771 | T39: 24浦鑫归航8C | U39: =XIRR(U40:U41,T40:T41) -> 0.050041315 | V39: =XIRR(V40:V41,T40:T41) -> 0.039991048
